Workbook
Name Taux_actualisation: '[1]Comptoir cosmétiques'!$B$5
Name Taux_d_actualisation: #REF!
Name Taux_d_amortissement: #REF!
Name Taux_d_impôt: #REF!
Name Tx_DAC: '[1]Comptoir cosmétiques'!$B$7
Name Tx_Impôt: '[1]Comptoir cosmétiques'!$B$6

Sheet BDL_Résultats
A1: BDL inc. RÉSULTATS Pour les exercices terminés le 31 décembre
E5: 2020 | G5: 2019 | I5: 2018 | K5: 2017 | M5: 2016 | P5: Variation
E6: (en milliers de dollars sauf pour les montants relatifs au bénéfice par action)
A9: CHIFFRE D'AFFAIRES | E9: 5450 | F9: =E9/$E$9 -> 1 | G9: 5350 | H9: =G9/$G$9 -> 1 | I9: 5250 | J9: =I9/$I$9 -> 1 | K9: 5000 | L9: =K9/$K$9 -> 1 | M9: 4500 | N9: =M9/$M$9 -> 1 | P9: =(E9-G9)/E9 -> 0.018348624
A10: Moins : rendus, rabais et escomptes | E10: =8%*E9 -> 436 | F10: =E10/$E$9 -> 0.08 | G10: =7%*G9 -> 374.5 | H10: =G10/$G$9 -> 0.07 | I10: =5%*I9 -> 262.5 | J10: =I10/$I$9 -> 0.05 | K10: =4%*K9 -> 200 | L10: =K10/$K$9 -> 0.04 | M10: =4%*M9 -> 180 | N10: =M10/$M$9 -> 0.04 | P10: =(E10-G10)/E10 -> 0.14105505
A11: Revenus nets | E11: =SUM(E9-E10) -> 5014 | G11: =SUM(G9-G10) -> 4975.5 | I11: =SUM(I9-I10) -> 4987.5 | K11: =SUM(K9-K10) -> 4800 | M11: =SUM(M9-M10) -> 4320
A13: COÛT DES PRODUITS VENDUS | E13: =62%*E9 -> 3379 | F13: =E13/$E$9 -> 0.62 | G13: =61%*G9 -> 3263.5 | H13: =G13/$G$9 -> 0.61 | I13: =60%*I9 -> 3150 | J13: =I13/$I$9 -> 0.6 | K13: =59%*K9 -> 2950 | L13: =K13/$K$9 -> 0.59 | M13: =58%*M9 -> 2610 | N13: =M13/$M$9 -> 0.58 | P13: =(E13-G13)/E13 -> 0.034181711
A15: BÉNÉFICE BRUT | E15: =E11-E13 -> 1635 | F15: =E15/$E$9 -> 0.3 | G15: =G11-G13 -> 1712 | H15: =G15/$G$9 -> 0.32 | I15: =I11-I13 -> 1837.5 | K15: =K11-K13 -> 1850 | L15: =K15/$K$9 -> 0.37 | M15: =M11-M13 -> 1710 | N15: =M15/$M$9 -> 0.38 | P15: =(E15-G15)/E15 -> -0.047094801
A17: Frais de vente et d'administration | E17: =17%*E9 -> 926.5 | F17: =E17/$E$9 -> 0.17 | G17: =16%*G9 -> 856 | H17: =G17/$G$9 -> 0.16 | I17: =14%*I9 -> 735 | J17: =I17/$I$9 -> 0.14 | K17: =13.5%*K9 -> 675 | L17: =K17/$K$9 -> 0.135 | M17: =13%*M9 -> 585 | N17: =M17/$M$9 -> 0.13 | P17: =(E17-G17)/E17 -> 0.076092822
A18: Amortissements | E18: =11.5%*BDL_Bilan!E16 -> 793.5 | F18: =E18/$E$9 -> 0.14559633 | G18: =11.5%*BDL_Bilan!G16 -> 770.5 | H18: =G18/$G$9 -> 0.14401869 | I18: =11.5%*BDL_Bilan!I16 -> 747.5 | J18: =I18/$I$9 -> 0.14238095 | K18: =11.5%*BDL_Bilan!K16 -> 690 | L18: =K18/$K$9 -> 0.138 | M18: =11.5%*BDL_Bilan!M16 -> 632.5 | N18: =M18/$M$9 -> 0.14055556 | P18: =(E18-G18)/E18 -> 0.028985507
A20: BÉNÉFICE D'EXPLOITATION | E20: =E15-E17-E18 -> -85 | F20: =E20/$E$9 -> -0.01559633 | G20: =G15-G17-G18 -> 85.5 | H20: =G20/$G$9 -> 0.015981308 | I20: =I15-I17-I18 -> 355 | J20: =I20/$I$9 -> 0.067619048 | K20: =K15-K17-K18 -> 485 | L20: =K20/$K$9 -> 0.097 | M20: =M15-M17-M18 -> 492.5 | N20: =M20/$M$9 -> 0.10944444 | P20: =(E20-G20)/E20 -> 2.0058824
A22: Frais financiers | E22: 272 | F22: =E22/$E$9 -> 0.049908257 | G22: 264 | H22: =G22/$G$9 -> 0.049345794 | I22: 256 | J22: =I22/$I$9 -> 0.048761905 | K22: 236 | L22: =K22/$K$9 -> 0.0472 | M22: 217 | N22: =M22/$M$9 -> 0.048222222 | P22: =(E22-G22)/E22 -> 0.029411765
A24: BÉNÉFICE (PERTE) AVANT IMPÔTS SUR LES BÉNÉFICES | E24: =E20-E22 -> -357 | F24: =E24/$E$9 -> -0.065504587 | G24: =G20-G22 -> -178.5 | H24: =G24/$G$9 -> -0.033364486 | I24: =I20-I22 -> 99 | J24: =I24/$I$9 -> 0.018857143 | K24: =K20-K22 -> 249 | L24: =K24/$K$9 -> 0.0498 | M24: =M20-M22 -> 275.5 | N24: =M24/$M$9 -> 0.061222222 | P24: =(E24-G24)/E24 -> 0.5
A26: IMPÔTS SUR LES BÉNÉFICES | E26: =32%*E24 -> -114.24 | F26: =E26/$E$9 -> -0.020961468 | G26: =32%*G24 -> -57.12 | H26: =G26/$G$9 -> -0.010676636 | I26: =32%*I24 -> 31.68 | J26: =I26/$I$9 -> 0.0060342857 | K26: =32%*K24 -> 79.68 | L26: =K26/$K$9 -> 0.015936 | M26: =32%*M24 -> 88.16 | N26: =M26/$M$9 -> 0.019591111 | P26: =(E26-G26)/E26 -> 0.5
A28: BÉNÉFICE NET (PERTE NETTE) | E28: =E24-E26 -> -242.76 | F28: =E28/$E$9 -> -0.044543119 | G28: =G24-G26 -> -121.38 | H28: =G28/$G$9 -> -0.02268785 | I28: =I24-I26 -> 67.32 | J28: =I28/$I$9 -> 0.012822857 | K28: =K24-K26 -> 169.32 | L28: =K28/$K$9 -> 0.033864 | M28: =M24-M26 -> 187.34 | N28: =M28/$M$9 -> 0.041631111 | P28: =(E28-G28)/E28 -> 0.5
A31: Marge brute | E31: =E15/E9 -> 0.3 | G31: =G15/G9 -> 0.32 | I31: =I15/I9 -> 0.35 | K31: =K15/K9 -> 0.37 | M31: =M15/M9 -> 0.38
A32: Marge nette | E32: =E28/E9 -> -0.044543119 | G32: =G28/G9 -> -0.02268785 | I32: =I28/I9 -> 0.012822857 | K32: =K28/K9 -> 0.033864 | M32: =M28/M9 -> 0.041631111
A34: Rendement sur capital Investi | E34: =E28/BDL_Bilan!E17 -> -0.02597511 | G34: =G28/BDL_Bilan!G17 -> -0.013437173 | I34: =I28/BDL_Bilan!I17 -> 0.0074785458 | K34: =K28/BDL_Bilan!K17 -> 0.01988024 | M34: =M28/BDL_Bilan!M17 -> 0.023703423
A35: Ratio d'endettement (P/A) | E35: =(BDL_Bilan!E27+BDL_Bilan!E24)/BDL_Bilan!E33 -> 0.47444381 | G35: =(BDL_Bilan!G27+BDL_Bilan!G24)/BDL_Bilan!G33 -> 0.47337593 | I35: =(BDL_Bilan!I27+BDL_Bilan!I24)/BDL_Bilan!I33 -> 0.45753856 | K35: =(BDL_Bilan!K27+BDL_Bilan!K24)/BDL_Bilan!K33 -> 0.43736417 | M35: =(BDL_Bilan!M27+BDL_Bilan!M24)/BDL_Bilan!M33 -> 0.42145885
A37: % de frais généraux | E37: =(E22+E18+E17)/E9 -> 0.36550459 | G37: =(G22+G18+G17)/G9 -> 0.35336449 | I37: =(I22+I18+I17)/I9 -> 0.33114286 | K37: =(K22+K18+K17)/K9 -> 0.3202 | M37: =(M22+M18+M17)/M9 -> 0.31877778
A38: Taux de rotation des actif | E38: =E9/BDL_Bilan!E17 -> 0.58314528 | G38: =G9/BDL_Bilan!G17 -> 0.59226294 | I38: =I9/BDL_Bilan!I17 -> 0.58321993 | K38: =K9/BDL_Bilan!K17 -> 0.58706117 | M38: =M9/BDL_Bilan!M17 -> 0.569368
A39: Taux de rotation des stocks | E39: =(BDL_Bilan!E12/BDL_Résultats!E13)*365 -> 127.75 | G39: =(BDL_Bilan!G12/BDL_Résultats!G13)*365 -> 109.5 | I39: =(BDL_Bilan!I12/BDL_Résultats!I13)*365 -> 102.2 | K39: =(BDL_Bilan!K12/BDL_Résultats!K13)*365 -> 94.9 | M39: =(BDL_Bilan!M12/BDL_Résultats!M13)*365 -> 91.25
A40: Delai de paiement des comptes clients | E40: =(BDL_Bilan!E10/BDL_Résultats!E9)*365 -> 77.234 | G40: =(BDL_Bilan!G10/BDL_Résultats!G9)*365 -> 67.89 | I40: =(BDL_Bilan!I10/BDL_Résultats!I9)*365 -> 62.415 | K40: =(BDL_Bilan!K10/BDL_Résultats!K9)*365 -> 56.064 | M40: =(BDL_Bilan!M10/BDL_Résultats!M9)*365 -> 52.56
A42: FDR | E42: =BDL_Bilan!E14/BDL_Bilan!E25 -> 2.4109593 | G42: =BDL_Bilan!G14/BDL_Bilan!G25 -> 3.8309279 | I42: =BDL_Bilan!I14/BDL_Bilan!I25 -> 4.1202773 | K42: =BDL_Bilan!K14/BDL_Bilan!K25 -> 4.4634782 | M42: =BDL_Bilan!M14/BDL_Bilan!M25 -> 4.8575182
A43: Liquidité immédiate | E43: =(BDL_Bilan!E14-BDL_Bilan!E12-BDL_Bilan!E13)/BDL_Bilan!E25 -> 1.1367597 | G43: =(BDL_Bilan!G14-BDL_Bilan!G12-BDL_Bilan!G13)/BDL_Bilan!G25 -> 2.026337 | I43: =(BDL_Bilan!I14-BDL_Bilan!I12-BDL_Bilan!I13)/BDL_Bilan!I25 -> 2.5029645 | K43: =(BDL_Bilan!K14-BDL_Bilan!K12-BDL_Bilan!K13)/BDL_Bilan!K25 -> 2.8905322 | M43: =(BDL_Bilan!M14-BDL_Bilan!M12-BDL_Bilan!M13)/BDL_Bilan!M25 -> 3.3043654

Sheet BDL_Bilan
A1: BDL inc BILAN Au 31 décembre
E5: 2020 | G5: 2019 | I5: 2018 | K5: 2017 | M5: 2016
A7: ACTIF
A8: Actif à court terme
A9: Espèces et quasi espèces | E9: 0 | F9: 0 | G9: 239 | H9: 0 | I9: 622 | J9: 0 | K9: 862 | L9: 0 | M9: 987
A10: Débiteurs | E10: =23%*BDL_Résultats!E11 -> 1153.22 | F10: =15%*BDL_Résultats!F11 -> 0 | G10: =20%*BDL_Résultats!G11 -> 995.1 | H10: =15%*BDL_Résultats!H11 -> 0 | I10: =18%*BDL_Résultats!I11 -> 897.75 | J10: =15%*BDL_Résultats!J11 -> 0 | K10: =16%*BDL_Résultats!K11 -> 768 | M10: =15%*BDL_Résultats!M11 -> 648
A11: Impôts à recevoir
A12: Stocks | E12: =35%*BDL_Résultats!E13 -> 1182.65 | F12: =25%*BDL_Résultats!F13 -> 0.155 | G12: =30%*BDL_Résultats!G13 -> 979.05 | H12: =25%*BDL_Résultats!H13 -> 0.1525 | I12: =28%*BDL_Résultats!I13 -> 882 | J12: =25%*BDL_Résultats!J13 -> 0.15 | K12: =26%*BDL_Résultats!K13 -> 767 | M12: =25%*BDL_Résultats!M13 -> 652.5
A13: Frais payés d'avance | E13: 110 | G13: 120 | H13: 110 | I13: 100 | K13: 120 | M13: 116
E14: =SUM(E9:E13) -> 2445.87 | F14: =SUM(F9:F13) -> 0.155 | G14: =SUM(G9:G13) -> 2333.15 | H14: =SUM(H9:H13) -> 110.1525 | I14: =SUM(I9:I13) -> 2501.75 | J14: =SUM(J9:J13) -> 0.15 | K14: =SUM(K9:K13) -> 2517 | L14: =SUM(L9:L13) -> 0 | M14: =SUM(M9:M13) -> 2403.5
A15: Actif à long terme
A16: Immobilisations | E16: 6900 | F16: =BDL_Résultats!F9*12 -> 12 | G16: 6700 | H16: =BDL_Résultats!H9*12 -> 12 | I16: 6500 | J16: =BDL_Résultats!J9*12 -> 12 | K16: 6000 | M16: 5500
E17: =SUM(E14:E16) -> 9345.87 | F17: =SUM(F14:F16) -> 12.155 | G17: =SUM(G14:G16) -> 9033.15 | H17: =SUM(H14:H16) -> 122.1525 | I17: =SUM(I14:I16) -> 9001.75 | J17: =SUM(J14:J16) -> 12.15 | K17: =SUM(K14:K16) -> 8517 | L17: =SUM(L14:L16) -> 0 | M17: =SUM(M14:M16) -> 7903.5
A19: PASSIF
A20: Passif à court terme
A21: Découvert de banque | E21: 293
A22: Créditeurs et frais courus | E22: =12%*BDL_Résultats!E13 -> 405.48 | F22: =8%*BDL_Résultats!F9 -> 0.08 | G22: =10%*BDL_Résultats!G13 -> 326.35 | H22: =8%*BDL_Résultats!H9 -> 0.08 | I22: =9%*BDL_Résultats!I13 -> 283.5 | J22: =8%*BDL_Résultats!J9 -> 0.08 | K22: =8.5%*BDL_Résultats!K13 -> 250.75 | M22: =8%*BDL_Résultats!M13 -> 208.8
A23: Impôts à payer | E23: 57 | F23: =BDL_Résultats!H26 -> -0.010676636 | G23: =BDL_Résultats!I26 -> 31.68 | H23: =BDL_Résultats!J26 -> 0.0060342857 | I23: =BDL_Résultats!K26 -> 79.68 | K23: =BDL_Résultats!M26 -> 88.16 | M23: =32%*250 -> 80
A24: Portion à court terme de la dette à long terme | E24: 259 | G24: 251 | H24: =5%*H27 -> 0.45 | I24: 244 | J24: =5%*J27 -> 0.45 | K24: 225 | L24: =5%*L27 -> 0 | M24: 206
E25: =SUM(E21:E24) -> 1014.48 | F25: =SUM(F21:F24) -> 0.069323364 | G25: =SUM(G21:G24) -> 609.03 | H25: =SUM(H21:H24) -> 0.53603429 | I25: =SUM(I21:I24) -> 607.18 | J25: =SUM(J21:J24) -> 0.53 | K25: =SUM(K21:K24) -> 563.91 | L25: =SUM(L21:L24) -> 0 | M25: =SUM(M21:M24) -> 494.8
A26: Passif à long terme
A27: Dette à long terme | E27: 4175 | F27: =75%*F16 -> 9 | G27: 4025 | H27: =75%*H16 -> 9 | I27: 3875 | J27: =75%*J16 -> 9 | K27: 3500 | M27: 3125
E28: =SUM(E25:E27) -> 5189.48 | F28: =SUM(F25:F27) -> 9.0693234 | G28: =SUM(G25:G27) -> 4634.03 | H28: =SUM(H25:H27) -> 9.5360343 | I28: =SUM(I25:I27) -> 4482.18 | J28: =SUM(J25:J27) -> 9.53 | K28: =SUM(K25:K27) -> 4063.91 | L28: =SUM(L25:L27) -> 0 | M28: =SUM(M25:M27) -> 3619.8
A29: CAPITAUX PROPRES
A30: Capital-actions | E30: 250 | F30: 250 | G30: 250 | H30: 250 | I30: 250 | J30: 250 | K30: 250 | M30: 250
A31: Bénéfices non répartis | E31: =G31+BDL_Résultats!E28 -> 3906.2 | F31: =H31+BDL_Résultats!F28 -> -0.06723097 | G31: =I31+BDL_Résultats!G28 -> 4148.96 | H31: =J31+BDL_Résultats!H28 -> -0.02268785 | I31: =K31+BDL_Résultats!I28 -> 4270.34 | K31: =M31+BDL_Résultats!K28 -> 4203.02 | M31: =M17-M28-M30 -> 4033.7
E32: =SUM(E30:E31) -> 4156.2 | F32: =SUM(F30:F31) -> 249.93277 | G32: =SUM(G30:G31) -> 4398.96 | H32: =SUM(H30:H31) -> 249.97731 | I32: =SUM(I30:I31) -> 4520.34 | J32: =SUM(J30:J31) -> 250 | K32: =SUM(K30:K31) -> 4453.02 | L32: =SUM(L30:L31) -> 0 | M32: =SUM(M30:M31) -> 4283.7
E33: =SUM(E32+E28) -> 9345.68 | F33: =SUM(F32+F28) -> 259.00209 | G33: =SUM(G32+G28) -> 9032.99 | H33: =SUM(H32+H28) -> 259.51335 | I33: =SUM(I32+I28) -> 9002.52 | J33: =SUM(J32+J28) -> 259.53 | K33: =SUM(K32+K28) -> 8516.93 | L33: =SUM(L32+L28) -> 0 | M33: =SUM(M32+M28) -> 7903.5

Sheet BDL_CR
A1: Informations sur le coût des produits vendus- année 2020
B2: Meubles usinés | C2: Meubles usinés finis main | D2: Meubles sur mesure | E2: Moyenne par unité pondérée | F2: Total en milliers de dollars
A3: Nombre de modèles
A4: Chiffre d'affaires (en milliers de $) | B4: 1907.5 | C4: 2452.5 | D4: 1090 | F4: 5450 | H4: Ne tient pas compte de l'escompte
A5: Volume de vente | B5: 2200 | C5: 1400 | D5: 400 | F5: 4000
A6: Prix de vente unitaire moyen avant escomptes | B6: 867.04545 | C6: 1751.7857 | D6: 2725 | E6: 1362.5 | F6: 1362.5
A7: Frais directs de fabrication unitaires
A8: Achats nets de matières premières | B8: 161.27045 | C8: 380.1375 | D8: 709.59 | E8: 292.70587 | F8: 1170.8235
A9: Main-d'œuvre directe | B9: 172.02182 | C9: 432.48786 | D9: 760.275 | E9: 322.01025 | F9: 1288.041
A10: Total frais directs | B10: 333.29227 | C10: 812.62536 | D10: 1469.865 | E10: 614.71613 | F10: 2458.8645
A11: Frais indirects de fabrication unitaires
A12: Fournitures de fabrication | B12: 19.659636 | C12: 49.427184 | D12: 86.888571 | E12: 36.801172 | F12: 147.20469
A13: Main-d’œuvre indirecte | B13: 44.234182 | C13: 111.21117 | D13: 195.49929 | E13: 82.802636 | F13: 331.21055
A14: Charges sociales | B14: 19.659636 | C14: 49.427184 | D14: 86.888571 | E14: 36.801172 | F14: 147.20469
A15: Énergie | B15: 7.3723636 | C15: 18.535194 | D15: 32.583214 | E15: 13.800439 | F15: 55.201758
A16: Entretien et réparations | B16: 14.744727 | C16: 37.070388 | D16: 65.166429 | E16: 27.600879 | F16: 110.40352
A17: Impôts fonciers | B17: 9.8298182 | C17: 24.713592 | D17: 43.444286 | E17: 18.400586 | F17: 73.602343
A18: Assurances | B18: 7.3723636 | C18: 18.535194 | D18: 32.583214 | E18: 13.800439 | F18: 55.201758
A19: Total frais indirects | B19: 122.87273 | C19: 308.9199 | D19: 543.05357 | E19: 230.00732 | F19: 920.02929
A20: Coût unitaire des marchandises vendues | B20: 456.165 | C20: 1121.5453 | D20: 2012.9186 | E20: 844.72345 | F20: 3378.8938
A21: Marge brute unitaire $ | B21: 410.88045 | C21: 630.24045 | D21: 712.08143 | E21: 517.77655 | F21: 2071.1062 | H21: Meubles sur mesure semblent plus rentables à l'unité
B22: =+B21/B6 -> 0.47388571 | C22: =+C21/C6 -> 0.35977029 | D22: =+D21/D6 -> 0.26131429 | H22: … mais le ratio indique que les meubles usinés ont une marge supérieure
B23: =B2 -> Meubles usinés | C23: =C2 -> Meubles usinés finis main | D23: =D2 -> Meubles sur mesure | E23: =E2 -> Moyenne par unité pondérée | F23: =F2 -> Total en milliers de dollars
A24: =A4 -> Chiffre d'affaires (en milliers de $) | B24: =B4 -> 1907.5 | C24: =C4 -> 2452.5 | D24: =D4 -> 1090 | F24: =SUM(B24:D24) -> 5450
A25: CMV total (en 000$) | B25: =B62 -> 1003.563 | C25: =C62 -> 1570.1634 | D25: =D62 -> 805.16743 | F25: =SUM(B25:D25) -> 3378.8938
A26: Marge brute | B26: =B24-B25 -> 903.937 | C26: =C24-C25 -> 882.33663 | D26: =D24-D25 -> 284.83257 | F26: =SUM(B26:D26) -> 2071.1062
A28: Pourcentage des ventes totales | B28: 0.35 | C28: 0.45 | D28: 0.2 | F28: =SUM(B28:D28) -> 1
A29: Pourcentage de contribution à la marge brute totale | B29: =B26/$F26 -> 0.4364513 | C29: =C26/$F26 -> 0.42602191 | D29: =D26/$F26 -> 0.13752678 | F29: =SUM(B29:D29) -> 1
A31: Marge brute % | B31: =B21/B6 -> 0.47388571 | C31: =C21/C6 -> 0.35977029 | D31: =D21/D6 -> 0.26131429 | F31: =F21/F4 -> 0.38001949
A32: Marge sur coûts variables | B32: =B6-B10 -> 533.75318 | C32: =C6-C10 -> 939.16035 | D32: =D6-D10 -> 1255.135 | F32: =F4-F10 -> 2991.1355
A33: % de MCV | B33: =B32/B6 -> 0.6156 | C33: =C32/C6 -> 0.536116 | D33: =D32/D6 -> 0.4606 | F33: =F32/F4 -> 0.5488322
A34: S.R. de fabrication | B34: =(B19*B5)/B32 -> 506.45131 | C34: =(C19*C5)/C32 -> 460.50482 | D34: =(D19*D5)/D32 -> 173.06619 | F34: =(F19*F5)/F32 -> 1230.3412
A35: Marge de sécurité de fabrication (%) | B35: =(B5-B34)/B5 -> 0.76979486 | C35: =(C5-C34)/C5 -> 0.67106799 | D35: =(D5-D34)/D5 -> 0.56733453 | F35: =(F5-F34)/F5 -> 0.6924147
B42: =B2 -> Meubles usinés | C42: =C2 -> Meubles usinés finis main | D42: =D2 -> Meubles sur mesure | E42: Total | F42: en 000$
A43: Escomptes | B43: 0.2 | C43: 0.35 | D43: 0.45 | E43: =SUM(B43:D43) -> 1 | F43: =BDL_Résultats!E10 -> 436
A45: Commissions | B45: 0.025 | C45: 0.05 | D45: 0.1 | F45: =(B45*B4)+(C45*C4)+(D45*D4) -> 279.3125
A46: Frais de transports | B46: 0.4 | C46: 0.4 | D46: 0.2 | E46: =SUM(B46:D46) -> 1 | F46: 185
A47: Frais d'assemblage | B47: 0.4 | C47: 0.35 | D47: 0.25 | E47: =SUM(B47:D47) -> 1 | F47: 45
A48: Frais de design | C48: 0.15 | D48: 0.85 | E48: =SUM(B48:D48) -> 1 | F48: 80
A49: Salaires administration | B49: % du CA | C49: % du CA | D49: % du CA | F49: 232
...
