Workbook
Name Financement_10_ans: Financement!$C$32:$L$33
Name Financement_5_ans: Financement!$C$49:$G$50

Sheet _TM_Feuil1
A1: Left | B1: Top | C1: Right | D1: Bottom | E1: Ref
A2: 1 | B2: 3 | C2: 11 | D2: 4 | E2: $A$3:$K$4
A3: 2 | B3: 8 | C3: 5 | D3: 11 | E3: $B$8:$E$11

Sheet _TM_Période optimale de remplac
A1: Left | B1: Top | C1: Right | D1: Bottom | E1: Ref
A2: 2 | B2: 2 | C2: 5 | D2: 8 | E2: $B$2:$E$8
A3: 2 | B3: 11 | C3: 6 | D3: 16 | E3: $B$11:$F$16
A4: 8 | B4: 17 | C4: 14 | D4: 21 | E4: $H$17:$N$21

Sheet _TM_Feuil2
A1: Left | B1: Top | C1: Right | D1: Bottom | E1: Ref
A2: 2 | B2: 2 | C2: 8 | D2: 5 | E2: $B$2:$H$5
A3: 3 | B3: 18 | C3: 5 | D3: 21 | E3: $C$18:$E$21
A4: 3 | B4: 22 | C4: 5 | D4: 26 | E4: $C$22:$E$26

Sheet Données
B1: Techniques d'analyse de projets d'investissement (pas à pas)
B3: Étape 1: Identification des données pertinentes
B4: Situation fictive mais basée sur un exemple réel)
B10: Autres informations présentées sous forme de tableau: | E10: Données présentées dans le texte à mettre en tableau
B11: Usine actuelle de Montréal
B12: Capacité (en tonnes) | C12: 150000 | E12: Amortissement usines | G12: 900000
B13: Tonnage traité annuellement | C13: 150000 | E13: Dette (4 ans) | G13: 2000000
B14: Prix de vente par tonne traitée | C14: 42 | E14: Remboursement annuel dette | G14: 500000
B15: Coût variable unitaire par tonne | C15: 19.75 | E15: Dividende annuel actionnaire | G15: 100000
B16: Coûts fixes | C16: 2500000 | E16: Durée du projet (ans) | G16: 10
E17: Taux d'intérêt | G17: 0.09
B18: Nouvelle usine à l'est Montréal | E18: Coût du capital | G18: 0.11
B19: Capacité (en tonnes) | C19: 400000 | E19: Taux d'impôt | G19: 0.3
B20: Tonnage traité annuellement | C20: 400000 | E20: Valeur résiduelle nouvelle usine | G20: 15000000
B21: Prix de vente par tonne traitée | C21: 42 | E21: Valeur résiduelle nouveau terrain | G21: 5000000
B22: Coût variable unitaire par tonne | C22: 21.25
B23: Coûts fixes | C23: 3000000
B24: Quantité de CO2 produite (KG) | C24: 1700000
B25: Prix de vente du CO2 (par KG) | C25: 2.15
B26: Investissement Fonds de roulement | C26: 1000000
B27: Investissement Terrain | C27: 10000000
B28: Investissement Usine (amort. 20%) | C28: 30000000
B30: Information manquante? Il faut poser une hypothèse sur le prix de vente de l'immeuble et du bâtiment
B31: Valeur au marché de l'usine de Montréal? | C31: 5000000
B32: Terrain | C32: =2000000 -> 2000000
B33: Bâtiment | C33: =C31-C32 -> 3000000
B35: Outils financiers pertinents?
B37: Étape 2: Calcul des flux monétaires pertinents
B39: Requis pour le calcul du financement | F39: Requis pour le calcul de la VAN
B40: Etats des résultats RECUP+ | D40: 3 usines | F40: Nouvelle Usine | H40: Marge Suppl.
B41: Revenus | D41: =$C$13*$C$14*3 -> 18900000 | F41: Revenus supp. annuel
B42: Coûts variables | D42: =-$C$13*$C$15*3 -> -8887500 | F42: Déchets | H42: =(Données!C20-Données!C13)*Données!C14 -> 10500000
B43: Marge sur coût variable | D43: =SUM(D41:D42) -> 10012500 | F43: CO2 | H43: =Données!C24*Données!C25 -> 3655000
B44: Amortissement | D44: =-G12 -> -900000 | H44: =SUM(H42:H43) -> 14155000
B45: Frais fixes | D45: =-$C$16*3 -> -7500000 | F45: Coûts supplémentaires
B46: Résultat d'exploitation | D46: =SUM(D43:D45) -> 1612500
B47: Frais financiers | D47: =-D60 -> -180000 | F47: Coûts variables | H47: =-((Données!C20*Données!C22)-(Données!C13*Données!C15)) -> -5537500
B48: Résultat net avant impôt | D48: =D46+D47 -> 1432500 | F48: Coûts fixes | H48: =-(Données!C23-Données!C16) -> -500000
B49: Impôts 30% | D49: =-D48*0.3 -> -429750 | F49: Flux monétaires avant impôt | H49: =SUM(H44:H48) -> 8117500
B50: Résultat net | D50: =SUM(D48:D49) -> 1002750 | F50: Impôts 30% | H50: =-0.3*H49 -> -2435250
...

Sheet VAN
A1: Étape 3: Calcul des flux actualisés
C2: Investissement | D2: VAEIACC | E2: Flux an 1 | F2: Flux an 2 | G2: Flux an 3 | H2: Flux an 4 | I2: Flux an 5 | J2: Flux an 6 | K2: Flux an 7 | L2: Flux an 8 | M2: Flux an 9 | N2: Flux an 10 | O2: Flux an 10
C3: =C8 -> -36000000 | D3: =D8 -> 3944399 | E3: =E7 -> 5682250 | F3: =F7 -> 5682250 | G3: =G7 -> 5682250 | H3: =H7 -> 5682250 | I3: =I7 -> 5682250 | J3: =J7 -> 5682250 | K3: =K7 -> 5682250 | L3: =L7 -> 5682250 | ... O3: =O7 -> 21000000
E4: (1+11%)1 | F4: (1+11%)2 | G4: (1+11%)3 | H4: (1+11%)4 | I4: (1+11%)5 | J4: (1+11%)6 | K4: (1+11%)7 | L4: (1+11%)8 | M4: (1+11%)9 | N4: (1+11%)10 | O4: (1+11%)10
C6: 0 | D6: 0 | E6: 1 | F6: 2 | G6: 3 | H6: 4 | I6: 5 | J6: 6 | K6: 7 | L6: 8 | M6: 9 | N6: 10 | O6: 10
B7: Projet | C7: =-(Données!C26+Données!C27+Données!C28-Données!C31) -> -36000000 | D7: =C19 -> 3944399 | E7: =Données!$H$51 -> 5682250 | F7: =Données!$H$51 -> 5682250 | G7: =Données!$H$51 -> 5682250 | H7: =Données!$H$51 -> 5682250 | I7: =Données!$H$51 -> 5682250 | J7: =Données!$H$51 -> 5682250 | K7: =Données!$H$51 -> 5682250 | L7: =Données!$H$51 -> 5682250 | ... N7: =Données!$H$51 -> 5682250 | O7: =Données!G20+Données!G21+Données!C26 -> 21000000
B8: Flux actualisés | C8: =C7*(1+Données!$G$18)^-C6 -> -36000000 | D8: =D7*(1+Données!$G$18)^-D6 -> 3944399 | E8: =E7*(1+Données!$G$18)^-E6 -> 5119144.1 | F8: =F7*(1+Données!$G$18)^-F6 -> 4611841.6 | G8: =G7*(1+Données!$G$18)^-G6 -> 4154812.2 | H8: =H7*(1+Données!$G$18)^-H6 -> 3743074.1 | I8: =I7*(1+Données!$G$18)^-I6 -> 3372138.8 | J8: =J7*(1+Données!$G$18)^-J6 -> 3037962.9 | ... O8: =O7*(1+Données!$G$18)^-O6 -> 7395874.1
B9: VAN | C9: =SUM(C8:O8) -> 8804361.7
B12: VAEIACC | C12: Usine
B13: Investissement | C13: =Données!C28-Données!C33 -> 27000000
B14: Taux d'impôt | C14: =Données!G19 -> 0.3
B15: Taux d'amortissement | C15: 0.2
B16: Rendement exigé | C16: =Données!G18 -> 0.11
B17: Valeur résiduelle | C17: =Données!G20 -> 15000000
B18: Durée de vie | C18: =Données!G16 -> 10
B19: VAEIACC | C19: =(((C13*C14*C15)/(C15+C16))*((1+(0.5*C16))/(1+C16)))-(((C17*C14*C15)/(C16+C15))*(1/((1+C16)^C18))) -> 3944399
D21: ou
D23: 1 | E23: 2 | F23: 3 | G23: 4 | H23: 5 | I23: 6 | J23: 7 | K23: 8 | L23: 9 | M23: 10
C24: Solde d'ouverture | D24: 0 | E24: =D29 -> 24300000 | F24: =E29 -> 19440000 | G24: =F29 -> 15552000 | H24: =G29 -> 12441600 | I24: =H29 -> 9953280 | J24: =I29 -> 7962624 | K24: =J29 -> 6370099.2 | L24: =K29 -> 5096079.4 | M24: =L29 -> 4076863.5
C25: ajout | D25: =C13 -> 27000000 | E25: 0 | F25: 0 | G25: 0 | H25: 0 | I25: 0 | J25: 0 | K25: 0 | L25: 0 | M25: 0
C26: demie année | D26: =-D25*0.5 -> -13500000 | E26: =-E25*0.5 -> 0 | F26: =-F25*0.5 -> 0 | G26: =-G25*0.5 -> 0 | H26: =-H25*0.5 -> 0 | I26: =-I25*0.5 -> 0 | J26: =-J25*0.5 -> 0 | K26: =-K25*0.5 -> 0 | ... M26: =-M25*0.5 -> 0
C27: montant de base | D27: =SUM(D24:D26) -> 13500000 | E27: =SUM(E24:E26) -> 24300000 | F27: =SUM(F24:F26) -> 19440000 | G27: =SUM(G24:G26) -> 15552000 | H27: =SUM(H24:H26) -> 12441600 | I27: =SUM(I24:I26) -> 9953280 | J27: =SUM(J24:J26) -> 7962624 | K27: =SUM(K24:K26) -> 6370099.2 | ... M27: =SUM(M24:M26) -> 4076863.5
C28: DPA | D28: =D27*$C$15 -> 2700000 | E28: =E27*$C$15 -> 4860000 | F28: =F27*$C$15 -> 3888000 | G28: =G27*$C$15 -> 3110400 | H28: =H27*$C$15 -> 2488320 | I28: =I27*$C$15 -> 1990656 | J28: =J27*$C$15 -> 1592524.8 | K28: =K27*$C$15 -> 1274019.8 | ... M28: =M27*$C$15 -> 815372.7
C29: cloture | D29: =D25-D28 -> 24300000 | E29: =E27-E28 -> 19440000 | F29: =F27-F28 -> 15552000 | G29: =G27-G28 -> 12441600 | H29: =H27-H28 -> 9953280 | I29: =I27-I28 -> 7962624 | J29: =J27-J28 -> 6370099.2 | K29: =K27-K28 -> 5096079.4 | L29: =L27-L28 -> 4076863.5 | M29: =M27-M28 -> 3261490.8
C31: DPA | D31: =D28 -> 2700000 | E31: =E28 -> 4860000 | F31: =F28 -> 3888000 | G31: =G28 -> 3110400 | H31: =H28 -> 2488320 | I31: =I28 -> 1990656 | J31: =J28 -> 1592524.8 | K31: =K28 -> 1274019.8 | ... M31: =M28 -> 815372.7
C32: taux d'impôt | D32: =$C$15 -> 0.2 | E32: =$C$15 -> 0.2 | F32: =$C$15 -> 0.2 | G32: =$C$15 -> 0.2 | H32: =$C$15 -> 0.2 | I32: =$C$15 -> 0.2 | J32: =$C$15 -> 0.2 | K32: =$C$15 -> 0.2 | ... M32: =$C$15 -> 0.2
C33: Économies d'impôts provenant de la DPA | D33: =D31*D32 -> 540000 | E33: =E31*E32 -> 972000 | F33: =F31*F32 -> 777600 | G33: =G31*G32 -> 622080 | H33: =H31*H32 -> 497664 | I33: =I31*I32 -> 398131.2 | J33: =J31*J32 -> 318504.96 | K33: =K31*K32 -> 254803.97 | ... M33: =M31*M32 -> 163074.54
A34: Étape 4: Calculer les autres indicateurs de performance
C37: =C7+D7 -> -32055601 | D37: =E7 -> 5682250 | E37: =F7 -> 5682250 | F37: =G7 -> 5682250 | G37: =H7 -> 5682250 | H37: =I7 -> 5682250 | I37: =J7 -> 5682250 | J37: =K7 -> 5682250 | K37: =L7 -> 5682250 | L37: =M7 -> 5682250 | M37: =N7+O7 -> 26682250
B38: TRI | C38: =IRR(C37:M37) -> 0.1611799
B41: Délai de récupération | C41: plus de 6 ans
C42: =C37 -> -32055601 | D42: =C42+D37 -> -26373351 | E42: =D42+E37 -> -20691101 | F42: =E42+F37 -> -15008851 | G42: =F42+G37 -> -9326601 | H42: =G42+H37 -> -3644351 | I42: =H42+I37 -> 2037899 | J42: =I42+J37 -> 7720149 | K42: =J42+K37 -> 13402399 | ... M42: =L42+M37 -> 45766899
B44: RCI
B45: Rendement moyen | C45: =AVERAGE(E7:N7) -> 5682250
B46: Amortissement moyen | C46: =-(-Données!C33+Données!C28-Données!G20)/10 -> -1200000 | D46: (hypothèse simpliste mais OK)
B47: Rendement net annuel | C47: =SUM(C45:C46) -> 4482250
B48: Capital investi | C48: =-C7 -> 36000000
B49: RCI | C49: =C47/C48 -> 0.12450694
B52: VAE | C52: Année 1
B53: Rendement net annuel | C53: =Données!H51 -> 5682250 | G53: .
...

Sheet Financement
A1: Étape 1: Calculer les besoins en financement
B3: 0 | C3: 1 | D3: 2 | E3: 3 | F3: 4 | G3: 5 | H3: 6 | I3: 7 | J3: 8 | K3: 9 | L3: 10
A4: Solde d'encaisse au début | B4: 0 | C4: =B20 -> 302750 | D4: =C20 -> 907750 | E4: =D20 -> 2304750 | F4: =E20 -> 3867350 | G4: =F20 -> 6134430 | H4: =G20 -> 8592094 | I4: =H20 -> 11265225 | J4: =I20 -> 14173730 | ... L4: =K20 -> 20757377
A5: Investissement intial net | B5: =VAN!C7 -> -36000000
A6: Fonds auto-générés actuels | B6: =(Données!$D$50-Données!$D$47-Données!$D$44) -> 2082750 | C6: =(Données!$D$50-Données!$D$47-Données!$D$44) -> 2082750 | D6: =(Données!$D$50-Données!$D$47-Données!$D$44) -> 2082750 | E6: =(Données!$D$50-Données!$D$47-Données!$D$44) -> 2082750 | F6: =(Données!$D$50-Données!$D$47-Données!$D$44) -> 2082750 | G6: =(Données!$D$50-Données!$D$47-Données!$D$44) -> 2082750 | H6: =(Données!$D$50-Données!$D$47-Données!$D$44) -> 2082750 | I6: =(Données!$D$50-Données!$D$47-Données!$D$44) -> 2082750 | ... L6: =(Données!$D$50-Données!$D$47-Données!$D$44) -> 2082750
A7: Fonds auto-générés supplémentaires | B7: 0 | C7: =Données!$H$51 -> 5682250 | D7: =Données!$H$51 -> 5682250 | E7: =Données!$H$51 -> 5682250 | F7: =Données!$H$51 -> 5682250 | G7: =Données!$H$51 -> 5682250 | H7: =Données!$H$51 -> 5682250 | I7: =Données!$H$51 -> 5682250 | J7: =Données!$H$51 -> 5682250 | ... L7: =Données!$H$51 -> 5682250
A8: Économies d'impôts sur amo immeuble | C8: =VAN!D33 -> 540000 | D8: =VAN!E33 -> 972000 | E8: =VAN!F33 -> 777600 | F8: =VAN!G33 -> 622080 | G8: =VAN!H33 -> 497664 | H8: =VAN!I33 -> 398131.2 | I8: =VAN!J33 -> 318504.96 | J8: =VAN!K33 -> 254803.97 | ... L8: =VAN!M33 -> 163074.54
A9: Dividende actionnaire | B9: =-Données!$G$15 -> -100000 | C9: =-Données!$G$15 -> -100000 | D9: =-Données!$G$15 -> -100000 | E9: =-Données!$G$15 -> -100000 | F9: =-Données!$G$15 -> -100000 | G9: =-Données!$G$15 -> -100000 | H9: =-Données!$G$15 -> -100000 | I9: =-Données!$G$15 -> -100000 | ... L9: =-Données!$G$15 -> -100000
A10: Fonds récupérés à la fin du projet | B10: 0 | C10: 0 | D10: 0 | E10: 0 | F10: 0 | G10: 0 | H10: 0 | I10: 0 | J10: 0 | K10: 0 | L10: 0
A11: Remboursement des intérêts-dette actuelle | B11: =-Données!D60 -> -180000 | C11: =-Données!E60 -> -135000 | D11: =-Données!F60 -> -90000 | E11: =-Données!G60 -> -45000
A12: Remboursement du capital-dette actuelle | B12: =-Données!D59 -> -500000 | C12: =-Données!E59 -> -500000 | D12: =-Données!F59 -> -500000 | E12: =-Données!G59 -> -500000 | F12: 0 | G12: 0 | H12: 0 | I12: 0 | J12: 0 | K12: 0 | L12: 0
A13: Surplus / (déficit) | B13: =SUM(B4:B12) -> -34697250 | C13: =SUM(C4:C12) -> 7872750 | D13: =SUM(D4:D12) -> 8954750 | E13: =SUM(E4:E12) -> 10202350 | F13: =SUM(F4:F12) -> 12154430 | G13: =SUM(G4:G12) -> 14297094 | H13: =SUM(H4:H12) -> 16655225 | I13: =SUM(I4:I12) -> 19248730 | ... L13: =SUM(L4:L12) -> 28585452
A15: Nouveau Financement
A16: Capital | B16: 0 | C16: =C32 -> -3500000 | D16: =D32 -> -3500000 | E16: =E32 -> -3500000 | F16: =F32 -> -3500000 | G16: =G32 -> -3500000 | H16: =H32 -> -3500000 | I16: =I32 -> -3500000 | J16: =J32 -> -3500000 | ... L16: =L32 -> -3500000
A17: Intérêts | B17: 0 | C17: =C33 -> -3465000 | D17: =D33 -> -3150000 | E17: =E33 -> -2835000 | F17: =F33 -> -2520000 | G17: =G33 -> -2205000 | H17: =H33 -> -1890000 | I17: =I33 -> -1575000 | J17: =J33 -> -1260000 | ... L17: =L33 -> -630000
A18: Surplus / (déficit) après remboursement | B18: =SUM(B13:B17) -> -34697250 | C18: =SUM(C13:C17) -> 907750 | D18: =SUM(D13:D17) -> 2304750 | E18: =SUM(E13:E17) -> 3867350 | F18: =SUM(F13:F17) -> 6134430 | G18: =SUM(G13:G17) -> 8592094 | H18: =SUM(H13:H17) -> 11265225 | I18: =SUM(I13:I17) -> 14173730 | ... L18: =SUM(L13:L17) -> 24455452
A19: Nouveau financement | B19: =F26 -> 35000000 | C19: 0 | D19: 0 | E19: 0 | F19: 0 | G19: 0 | H19: 0 | I19: 0 | J19: 0 | K19: 0 | L19: 0
A20: Solde d'encaisse à la fin | B20: =SUM(B18:B19) -> 302750 | C20: =SUM(C18:C19) -> 907750 | D20: =SUM(D18:D19) -> 2304750 | E20: =SUM(E18:E19) -> 3867350 | F20: =SUM(F18:F19) -> 6134430 | G20: =SUM(G18:G19) -> 8592094 | H20: =SUM(H18:H19) -> 11265225 | I20: =SUM(I18:I19) -> 14173730 | ... L20: =SUM(L18:L19) -> 24455452
A26: Étape 2: Estimer le montant de financement nécessaire maintenir un surplus sur 10 ans | F26: 35000000
A28: Étape 3: Calculer le montant des intérêts sur 10 ans
B30: Année | C30: 1 | D30: 2 | E30: 3 | F30: 4 | G30: 5 | H30: 6 | I30: 7 | J30: 8 | K30: 9 | L30: 10
B31: Solde départ | C31: =B19 -> 35000000 | D31: =C34 -> 31500000 | E31: =D34 -> 28000000 | F31: =E34 -> 24500000 | G31: =F34 -> 21000000 | H31: =G34 -> 17500000 | I31: =H34 -> 14000000 | J31: =I34 -> 10500000 | K31: =J34 -> 7000000 | L31: =K34 -> 3500000
B32: Capital | C32: =-C31/10 -> -3500000 | D32: =C32 -> -3500000 | E32: =D32 -> -3500000 | F32: =E32 -> -3500000 | G32: =F32 -> -3500000 | H32: =G32 -> -3500000 | I32: =H32 -> -3500000 | J32: =I32 -> -3500000 | K32: =J32 -> -3500000 | L32: =K32 -> -3500000
B33: Intérêts | C33: =-$B$36*(C31-C32) -> -3465000 | D33: =-$B$36*(D31-D32) -> -3150000 | E33: =-$B$36*(E31-E32) -> -2835000 | F33: =-$B$36*(F31-F32) -> -2520000 | G33: =-$B$36*(G31-G32) -> -2205000 | H33: =-$B$36*(H31-H32) -> -1890000 | I33: =-$B$36*(I31-I32) -> -1575000 | J33: =-$B$36*(J31-J32) -> -1260000 | ... L33: =-$B$36*(L31-L32) -> -630000
B34: Solde fin | C34: =IF(C31+C32<0,0,C31+C32) -> 31500000 | D34: =IF(D31+D32<0,0,D31+D32) -> 28000000 | E34: =IF(E31+E32<0,0,E31+E32) -> 24500000 | F34: =IF(F31+F32<0,0,F31+F32) -> 21000000 | G34: =IF(G31+G32<0,0,G31+G32) -> 17500000 | H34: =IF(H31+H32<0,0,H31+H32) -> 14000000 | I34: =IF(I31+I32<0,0,I31+I32) -> 10500000 | J34: =IF(J31+J32<0,0,J31+J32) -> 7000000 | ... L34: =IF(L31+L32<0,0,L31+L32) -> 0
B36: =Données!G17 -> 0.09
A38: Étape 4: Compléter le budget de caisse à partir du tableau précédent
A40: Étape 5: Ajuster le montant du financement nécessaire ou du terme au besoin (versements anticipés)
B41: 0 | C41: 1 | D41: 2 | E41: 3 | F41: 4 | G41: 5 | H41: 6 | I41: 7 | J41: 8 | K41: 9 | L41: 10
A42: Liquiditées annuelles | B42: . | C42: =C18-C4 -> 605000 | D42: =D18-D4 -> 1397000 | E42: =E18-E4 -> 1562600 | F42: =F18-F4 -> 2267080 | G42: =G18-G4 -> 2457664 | H42: =H18-H4 -> 2673131.2 | I42: =I18-I4 -> 2908505 | J42: =J18-J4 -> 3159804 | ... L42: =L18-L4 -> 3698074.5
A43: Liquidités cumulées: | D43: =C42+D42 -> 2002000 | E43: =D43+E42 -> 3564600 | F43: =E43+F42 -> 5831680 | G43: =F43+G42 -> 8289344 | H43: =G43+H42 -> 10962475 | I43: =H43+I42 -> 13870980 | J43: =I43+J42 -> 17030784 | K43: =J43+K42 -> 20454627 | L43: =K43+L42 -> 24152702
A45: Étape 6: Calculer la possibilité d'accroître les versements en réduisant le terme
A46: Voir étape 3
B47: Année | C47: 1 | D47: 2 | E47: 3 | F47: 4 | G47: 5 | H47: 6 | I47: 7
B48: Solde départ | C48: =B19 -> 35000000 | D48: =C51 -> 30000000 | E48: =D51 -> 25000000 | F48: =E51 -> 20000000 | G48: =F51 -> 15000000 | H48: =G51 -> 10000000 | I48: =H51 -> 5000000
B49: Capital | C49: =-C48/7 -> -5000000 | D49: =C49 -> -5000000 | E49: =D49 -> -5000000 | F49: =E49 -> -5000000 | G49: =F49 -> -5000000 | H49: =G49 -> -5000000 | I49: =H49 -> -5000000
B50: Intérêts | C50: =-$B$36*(C48-C49) -> -3600000 | D50: =-$B$36*(D48-D49) -> -3150000 | E50: =-$B$36*(E48-E49) -> -2700000 | F50: =-$B$36*(F48-F49) -> -2250000 | G50: =-$B$36*(G48-G49) -> -1800000 | H50: =-$B$36*(H48-H49) -> -1350000 | I50: =-$B$36*(I48-I49) -> -900000
B51: Solde fin | C51: =IF(C48+C49<0,0,C48+C49) -> 30000000 | D51: =IF(D48+D49<0,0,D48+D49) -> 25000000 | E51: =IF(E48+E49<0,0,E48+E49) -> 20000000 | F51: =IF(F48+F49<0,0,F48+F49) -> 15000000 | G51: =IF(G48+G49<0,0,G48+G49) -> 10000000 | H51: =IF(H48+H49<0,0,H48+H49) -> 5000000 | I51: =IF(I48+I49<0,0,I48+I49) -> 0
B53: =B36 -> 0.09
A56: Étape 7: Calculer les ratios de financement si requis
...
