Workbook

Sheet PPP-déchets organiques
A1: Analyse de projet d'investissement PPP
B3: Année 0 | C3: 2022 | D3: 2023 | E3: 2024 | F3: 2025 | G3: 2026 | H3: 2027 | I3: 2028 | J3: 2029 | K3: 2030 | L3: 2031 | M3: 2032 | N3: 2033 | O3: 2034 | P3: 2035 | Q3: 2036 | R3: 2037 | S3: 2038 | T3: 2039 | U3: 2040 | V3: 2041 | W3: 2042 | X3: 2043 | Y3: 2044 | Z3: 2045 | AA3: 2046 | AB3: 2047 | AC3: 2048 | AD3: 2049 | AE3: 2050 | AF3: 2051
A5: Matriel (Catégorie 53) | B5: =-12000000 -> -12000000
A7: Débours
A8: Frais annuel MU | C8: =+L27 -> 78 | D8: =+C8*(100%+$L29) -> 79.56 | E8: =+D8*(100%+$L29) -> 81.1512 | F8: =+E8*(100%+$L29) -> 82.774224 | G8: =+F8*(100%+$L29) -> 84.429708 | H8: =+G8*(100%+$L29) -> 86.118303 | I8: =+H8*(100%+$L29) -> 87.840669 | J8: =+I8*(100%+$L29) -> 89.597482 | K8: =+J8*(100%+$L29) -> 91.389432 | ... AF8: =+AE8*(100%+$L29) -> 138.51589
A9: Nombre client MU | C9: =+C34 -> 150000 | D9: =+D34 -> 157000 | E9: =+E34 -> 158000 | F9: =+F34 -> 160000 | G9: =+G34 -> 163000 | H9: =+H34 -> 165000 | I9: =+I34 -> 167000 | J9: =+I9+(I9*$L32) -> 167835 | K9: =+J9+(J9*$L32) -> 168674.17 | L9: =+K9+(K9*$L32) -> 169517.55 | M9: =+L9+(L9*$L32) -> 170365.13 | N9: =+M9+(M9*$L32) -> 171216.96 | O9: =+N9+(N9*$L32) -> 172073.04 | P9: =+O9+(O9*$L32) -> 172933.41 | Q9: =+P9+(P9*$L32) -> 173798.08 | ... AF9: =+AE9+(AE9*$L32) -> 187299.19
A10: Vente ménages unifamiliaux | C10: =+C9*C8 -> 11700000 | D10: =+D9*D8 -> 12490920 | E10: =+E9*E8 -> 12821890 | F10: =+F9*F8 -> 13243876 | G10: =+G9*G8 -> 13762042 | H10: =+H9*H8 -> 14209520 | I10: =+I9*I8 -> 14669392 | J10: =+J9*J8 -> 15037593 | ... AF10: =+AF9*AF8 -> 25943913
A11: Vente clients commerciaux | C11: =+C35 -> 3500000 | D11: =+D35 -> 3600000 | E11: =+E35 -> 3700000 | F11: =+F35 -> 3800000 | G11: =+G35 -> 3900000 | H11: =+H35 -> 4000000 | I11: =+I35 -> 4100000 | J11: =+I11+(I11*($L33)) -> 4141000 | K11: =+J11+(J11*($L33)) -> 4182410 | L11: =+K11+(K11*($L33)) -> 4224234.1 | M11: =+L11+(L11*($L33)) -> 4266476.4 | N11: =+M11+(M11*($L33)) -> 4309141.2 | O11: =+N11+(N11*($L33)) -> 4352232.6 | P11: =+O11+(O11*($L33)) -> 4395754.9 | Q11: =+P11+(P11*($L33)) -> 4439712.5 | ... AF11: =+AE11+(AE11*($L33)) -> 5154368.4
A12: Vente Compost | C12: 1250000 | D12: =+C12+(C12*$L29) -> 1275000 | E12: =+D12+(D12*$L29) -> 1300500 | F12: =+E12+(E12*$L29) -> 1326510 | G12: =+F12+(F12*$L29) -> 1353040.2 | H12: =+G12+(G12*$L29) -> 1380101 | I12: =+H12+(H12*$L29) -> 1407703 | J12: =+I12+(I12*$L29) -> 1435857.1 | K12: =+J12+(J12*$L29) -> 1464574.2 | ... AF12: =+AE12+(AE12*$L29) -> 2219805.9
A13: Total revenues | C13: =+SUM(C10:C12) -> 16450000 | D13: =+SUM(D10:D12) -> 17365920 | E13: =+SUM(E10:E12) -> 17822390 | F13: =+SUM(F10:F12) -> 18370386 | G13: =+SUM(G10:G12) -> 19015083 | H13: =+SUM(H10:H12) -> 19589621 | I13: =+SUM(I10:I12) -> 20177095 | J13: =+SUM(J10:J12) -> 20614450 | ... AF13: =+SUM(AF10:AF12) -> 33318087
A14: Sortie de fond
A15: Cout de collecte | C15: 6000000 | D15: =+C15+(C15*$L29) -> 6120000 | E15: =+D15+(D15*$L29) -> 6242400 | F15: =+E15+(E15*$L29) -> 6367248 | G15: =+F15+(F15*$L29) -> 6494593 | H15: =+G15+(G15*$L29) -> 6624484.8 | I15: =+H15+(H15*$L29) -> 6756974.5 | J15: =+I15+(I15*$L29) -> 6892114 | K15: =+J15+(J15*$L29) -> 7029956.3 | ... AF15: =+AE15+(AE15*$L29) -> 10655068
A16: Cout exploitation usine | C16: 6500000 | D16: =+C16+(C16*$L29) -> 6630000 | E16: =+D16+(D16*$L29) -> 6762600 | F16: =+E16+(E16*$L29) -> 6897852 | G16: =+F16+(F16*$L29) -> 7035809 | H16: =+G16+(G16*$L29) -> 7176525.2 | I16: =+H16+(H16*$L29) -> 7320055.7 | J16: =+I16+(I16*$L29) -> 7466456.8 | K16: =+J16+(J16*$L29) -> 7615786 | ... AF16: =+AE16+(AE16*$L29) -> 11542990
A17: Total cout exploitation | C17: =+SUM(C15:C16) -> 12500000 | D17: =+SUM(D15:D16) -> 12750000 | E17: =+SUM(E15:E16) -> 13005000 | F17: =+SUM(F15:F16) -> 13265100 | G17: =+SUM(G15:G16) -> 13530402 | H17: =+SUM(H15:H16) -> 13801010 | I17: =+SUM(I15:I16) -> 14077030 | J17: =+SUM(J15:J16) -> 14358571 | ... AF17: =+SUM(AF15:AF16) -> 22198059
A19: Flux de trésorerie avant impot | C19: =+C13-C17 -> 3950000 | D19: =+D13-D17 -> 4615920 | E19: =+E13-E17 -> 4817389.6 | F19: =+F13-F17 -> 5105285.8 | G19: =+G13-G17 -> 5484680.7 | H19: =+H13-H17 -> 5788610.9 | I19: =+I13-I17 -> 6100064.5 | J19: =+J13-J17 -> 6255879.6 | ... AF19: =+AF13-AF17 -> 11120028
A20: Quote de part de WDI | C20: =+C19*$L31 -> 1975000 | D20: =+D19*$L31 -> 2307960 | E20: =+E19*$L31 -> 2408694.8 | F20: =+F19*$L31 -> 2552642.9 | G20: =+G19*$L31 -> 2742340.3 | H20: =+H19*$L31 -> 2894305.5 | I20: =+I19*$L31 -> 3050032.2 | J20: =+J19*$L31 -> 3127939.8 | ... AF20: =+AF19*$L31 -> 5560014.2
A21: Impot | C21: =+C20*$L34 -> 523375 | D21: =+D20*$L34 -> 611609.4 | E21: =+E20*$L34 -> 638304.12 | F21: =+F20*$L34 -> 676450.37 | G21: =+G20*$L34 -> 726720.19 | H21: =+H20*$L34 -> 766990.94 | I21: =+I20*$L34 -> 808258.54 | J21: =+J20*$L34 -> 828904.05 | ... AF21: =+AF20*$L34 -> 1473403.8
A22: Économie d'impot lié a l'ortissement | B22: =-(B5*L34*L36)/(L35+L36)*L31 -> 1204545.5
A23: FM net d'impot | B23: =SUM(B5:B22) -> -10795455 | C23: =+C20-C21 -> 1451625 | D23: =+D20-D21 -> 1696350.6 | E23: =+E20-E21 -> 1770390.7 | F23: =+F20-F21 -> 1876192.5 | G23: =+G20-G21 -> 2015620.2 | H23: =+H20-H21 -> 2127314.5 | I23: =+I20-I21 -> 2241773.7 | J23: =+J20-J21 -> 2299035.8 | ... AF23: =+AF20-AF21 -> 4086610.4
A25: VAN | B25: =+NPV(L35,C23:AF23)+B23 -> 2225721.2
H27: taux d'actualisation il est dans le texte | K27: Facturation par année MU | L27: =6.5*12 -> 78
K28: Capacité annuelle | L28: 75000 | M28: Tonnes
K29: Taux d'inflation | L29: 0.02
K30: Employés embauchés | L30: 36
K31: Quote par de bénifice net avant impot | L31: 0.5
K32: Croissance annuelle nombre MU | L32: 0.005
C33: 2022 | D33: 2023 | E33: 2024 | F33: 2025 | G33: 2026 | H33: 2027 | I33: 2028 | K33: Croissance vente CM | L33: 0.01 | M33: Hypothese augmentation annuelle a partir de fin 2028
B34: Nombre de ménages unifamiliaux | C34: 150000 | D34: 157000 | E34: 158000 | F34: 160000 | G34: 163000 | H34: 165000 | I34: 167000 | K34: Taux d'imposition | L34: 0.265
B35: Autres clients commerciaux | C35: 3500000 | D35: 3600000 | E35: 3700000 | F35: 3800000 | G35: 3900000 | H35: 4000000 | I35: 4100000 | K35: I | L35: 0.16
K36: D | L36: 0.5

Sheet Services conseils_x0009_
B1: Option 2 : Prestation de services-conseils
D4: Annexe I Option 2 : Services-conseils
D6: 1 | E6: 2 | F6: 3
B7: Services-conseils : | C7: 2021 (9 mois) | D7: 2022 | E7: 2023 | F7: 2024 | G7: Hypothèses/justification
B8: Produits :
B9: Services-conseils | C9: =SUMPRODUCT(C64:C67,C72:C75,$G$73:$G$76) -> 1675000 | D9: =SUMPRODUCT(D64:D67,D72:D75,$G$73:$G$76) -> 2756000 | E9: =SUMPRODUCT(E64:E67,E72:E75,$G$73:$G$76) -> 2846000 | F9: =SUMPRODUCT(F64:F67,F72:F75,$G$73:$G$76) -> 3627500
B10: Charges :
B11: Salaires | C11: =-SUMPRODUCT($G$65:$G$69,C64:C68)*75% -> -740250 | D11: =-SUMPRODUCT($G$65:$G$69,D64:D68)*(1+$C$80)^D6 -> -1266840 | E11: =-SUMPRODUCT($G$65:$G$69,E64:E68)*(1+$C$80)^E6 -> -1292176.8 | F11: =-SUMPRODUCT($G$65:$G$69,F64:F68)*(1+$C$80)^F6 -> -1588628.4 | G11: Selon les employés et le salaire annuel, avec inflation
B12: Avantages sociaux | C12: =C11*25% -> -185062.5 | D12: =D11*25% -> -316710 | E12: =E11*25% -> -323044.2 | F12: =F11*25% -> -397157.09 | G12: 25% des salaires versés, comme le reste de WDI
B13: Charges d'exploitation | C13: =C11*23% -> -170257.5 | D13: =D11*23% -> -291373.2 | E13: =E11*23% -> -297200.66 | F13: =F11*23% -> -365384.53 | G13: 23% des salaires (déjà ajustés avec l'inflation)
B14: Marketing et dépenses connexes | C14: =-350000 -> -350000 | D14: -400000 | E14: -250000 | F14: -250000 | G14: Incluant les frais de représentation déductibles à 50%
B15: Charges totales | C15: =SUM(C11:C14) -> -1445570 | D15: =SUM(D11:D14) -> -2274923.2 | E15: =SUM(E11:E14) -> -2162421.7 | F15: =SUM(F11:F14) -> -2601170
B17: Bénéfice d'exploitation | C17: =C9+C15 -> 229430 | D17: =D9+D15 -> 481076.8 | E17: =E9+E15 -> 683578.34 | F17: =F9+F15 -> 1026330
B18: Impôt sur les bénéfices (26,5%) | C18: =-C17*26.5% -> -60798.95 | D18: =-D17*26.5% -> -127485.35 | E18: =-E17*26.5% -> -181148.26 | F18: =-F17*26.5% -> -271977.45
B19: Bénéfice net de la division | C19: =SUM(C17:C18) -> 168631.05 | D19: =SUM(D17:D18) -> 353591.45 | E19: =SUM(E17:E18) -> 502430.08 | F19: =SUM(F17:F18) -> 754352.55
B21: Marge d'exploitation | C21: =C17/C9 -> 0.13697313 | D21: =D17/D9 -> 0.17455617 | E21: =E17/E9 -> 0.24018916 | F21: =F17/F9 -> 0.28293039
B24: Bénéfice différenciel - impact sur les activités actuelles
B25: Coût de renonciation découlant des recommandations perdues | C25: =-600000*0.75 -> -450000 | D25: -600000 | E25: -600000 | F25: -600000 | G25: Application de la marge avant impôt, excluant l'amortissement car fixe, pour estimer les produits et charges des recommandations perdues
B26: Honoraires épargnés | C26: =250000*1.7*75% -> 318750 | D26: =250000*1.7 -> 425000 | E26: =250000*1.7 -> 425000 | F26: =250000*1.7 -> 425000
B27: Bénéfice d'exploitation perdu | C27: =SUM(C25:C26) -> -131250 | D27: =SUM(D25:D26) -> -175000 | E27: =SUM(E25:E26) -> -175000 | F27: =SUM(F25:F26) -> -175000 | G27: En prenant en compte l'augmentation future des honoraires
B28: Impôt sur les bénéfices (26,5%) | C28: =-C27*26.5% -> 34781.25 | D28: =-D27*26.5% -> 46375 | E28: =-E27*26.5% -> 46375 | F28: =-F27*26.5% -> 46375
B29: Bénéfice net perdu | C29: =SUM(C27:C28) -> -96468.75 | D29: =SUM(D27:D28) -> -128625 | E29: =SUM(E27:E28) -> -128625 | F29: =SUM(F27:F28) -> -128625
B31: Bénéfice d'exploitation différentiel | C31: =C17+C27 -> 98180 | D31: =D17+D27 -> 306076.8 | E31: =E17+E27 -> 508578.34 | F31: =F17+F27 -> 851330
B33: Bénéfice net différentiel | C33: =C19+C29 -> 72162.3 | D33: =D19+D29 -> 224966.45 | E33: =E19+E29 -> 373805.08 | F33: =F19+F29 -> 625727.55
B35: Marge d'exploitation différentielle | C35: =C31/C9 -> 0.058614925 | D35: =D31/D9 -> 0.11105835 | E35: =E31/E9 -> 0.17869935 | F35: =F31/F9 -> 0.2346878
B37: Flux de trésorerie disponibles
B38: Bénéfice net différentiel | C38: =C33 -> 72162.3 | D38: =D33 -> 224966.45 | E38: =E33 -> 373805.08 | F38: =F33 -> 625727.55
B39: Variation des comptes clients
B40: Solde d'ouverture des comptes clients | C40: 0 | D40: =C41 -> 213182 | E40: =D41 -> 264274 | F40: =E41 -> 272904
B41: Clients non encaissés fin d'année | C41: =ROUND(C9*35/275,0) -> 213182 | D41: =ROUND(D9*35/365,0) -> 264274 | E41: =ROUND(E9*35/365,0) -> 272904 | F41: =ROUND(F9*35/365,0) -> 347842
B42: Variation des comptse clients | C42: =C40-C41 -> -213182 | D42: =D40-D41 -> -51092 | E42: =E40-E41 -> -8630 | F42: =F40-F41 -> -74938
B44: Flux de trésorerie nets (objectif) | C44: =C38+C42 -> -141019.7 | D44: =D38+D42 -> 173874.45 | E44: =E38+E42 -> 365175.08 | F44: =F38+F42 -> 550789.55
B46: Flux de trésorerie nets (en proportion de l'objectif) | C46: =C44/1700000 -> -0.082952765 | D46: =D44/1700000 -> 0.10227909 | E46: =E44/1700000 -> 0.21480887 | F46: =F44/1700000 -> 0.32399385
C49: Heures facturables utilisées par semaine
B50: Thom Lancaster | C50: =C72/(52-4) -> 14.583333 | D50: =D72/(52-4) -> 16.666667 | E50: =E72/(52-4) -> 16.666667 | F50: =F72/(52-4) -> 16.666667
B51: Techniciens | C51: =C73/(52-4) -> 20.833333 | D51: =D73/(52-4) -> 27.083333 | E51: =E73/(52-4) -> 27.083333 | F51: =F73/(52-4) -> 27.083333 | G51: Hypothèse : 4 semaines de vacances par année
B52: Techniciens superviseurs | C52: =C74/(52-4) -> 16.666667 | D52: =D74/(52-4) -> 21.875 | E52: =E74/(52-4) -> 22.916667 | F52: =F74/(52-4) -> 25
B53: Ingénieurs principaux | C53: =C75/(52-4) -> 16.666667 | D53: =D75/(52-4) -> 21.875 | E53: =E75/(52-4) -> 22.916667 | F53: =F75/(52-4) -> 23.958333
B61: Données utilisées pour les calculs ci-dessus
C62: Nombre d’employés
...

Sheet Recyclage-MCV
A1: Option 3 - Usines de recyclage -Analyse de la MCV et de la perte découlant de la fermeture temporaire
A3: Objectif : Calculer la marge sur coûts variables des diverses matières recyclables ET déterminer la marge sur coûts variables différentielle ou la perte découlant de la fermeture temporaire de la division du recyclage.
C4: Note | D4: Carton ondulé | E4: Papiers mélangés | F4: Verre | G4: Total pour les matières recyclables actuelles | I4: Plastiques PET | J4: Aluminium
B5: Ventes | C5: Voir page 20 22 45 | D5: 126 | E5: 2.3 | F5: 0.5 | G5: =(70*D14)+(1.1*E14)+(1.4*F14) -> 4366000 | I5: 520 | J5: 2030
B6: Remise | D6: 50 | E6: 1 | F6: 1 | G6: =(50*D14)+(1*E14)+(1*F14) -> 3140000 | I6: =+I5*C27 -> 156 | J6: =+J5*C27 -> 609
B7: Cout variables | D7: 15 | E7: 2.1 | F7: 1.92 | I7: 250 | J7: 1080
B8: MCV unitaires | D8: =+D5-D6-D7 -> 61 | E8: =+E5-E6-E7 -> -0.8 | F8: =+F5-F6-F7 -> -2.42 | I8: =+I5-I6-I7 -> 114 | J8: =+J5-J6-J7 -> 341
B9: Marge sur coûts variables liée à la vente de matières recyclées traitées | D9: =+D8*D14 -> 3660000 | E9: =+E8*E14 -> -80000 | F9: =+F8*F14 -> -96800 | G9: =+G5-G6 -> 1226000 | I9: =+(I5-I6-I7)*I14 -> 3420000 | J9: =+(J5-J6-J7)*J14 -> 6820000
B11: les cout d'éxploitation supplémetaires | C11: 270000
B14: Tonnes recus | D14: 60000 | E14: 100000 | F14: 40000 | I14: 30000 | J14: 20000
B16: Perte de MCV sur les diverses matieres recyclables | C16: =+D9+E9+F9 -> 3483200
B17: (hypothése WDI traite les matieres recyclées)
B18: MCV pour les matieres recyclables | C18: =+G9 -> 1226000
B20: Perte temporaire découlant de la fermeture de la division recyclage | C20: =+C16-C18 -> 2257200
B24: les cout d'éxploitation supplémentaires minimaux de 270 000 annuelement pour entretenir les batiments et le matériel et prévenir la détérioration pendant la fermeture
B27: Remise pour le plastique PET et l'aluminium | C27: 0.3
B28: On fait les calculs pour 2021
C29: la capacité annuelle de traitement des 4 usines | E29: 200000 | F29: Tonnes
B30: les couts de main d'ouvre les autres couts d'éxploitations et l'amortissments ont fixes

Sheet Recyclage - Rentabilité
A1: Option 3 - Usines de recyclage - analyse de rentabilité
A3: Objectif : Calculer le bénéfice d’exploitation et le bénéfice net des différents scénarios pour la division du recyclage.
F5: Scénario 2 | G5: Scénario 3 – 1 | H5: Scénario 3 – 2
F6: Recyclage carton ondulé, vente verre et papiers | G6: Recyclage carton ondulé, ajout aluminium | H6: Recyclage carton ondulé, ajout plastiques
B7: Chiffre d'affaire | F7: =+SUM(F8:F12) -> 7726000 | G7: =+SUM(G8:G12) -> 48304000 | H7: =+SUM(H8:H12) -> 23293000
B8: Recyclage carton ondulé | F8: =+'Recyclage-MCV'!D5*'Recyclage-MCV'!D14 -> 7560000 | G8: =+F8 -> 7560000 | H8: =+G8 -> 7560000
B9: Vente verre | F9: =1.4*40000 -> 56000 | G9: =+F9 -> 56000 | H9: =+G9 -> 56000
B10: Vente papier | F10: =1.1*100000 -> 110000 | G10: =1.1*80000 -> 88000 | H10: =70000*1.1 -> 77000
B11: Vente Aluminium | G11: =+'Recyclage-MCV'!J5*'Recyclage-MCV'!J14 -> 40600000
B12: Vente Plastique | H12: =30000*520 -> 15600000
B13: CMV Recyclage carton ondulé | F13: =-('Recyclage-MCV'!D6+'Recyclage-MCV'!D7)*'Recyclage-MCV'!D14 -> -3900000 | G13: =+F13 -> -3900000 | H13: =+G13 -> -3900000
B14: CMV verre | F14: =-1*40000 -> -40000 | G14: =+F14 -> -40000 | H14: =+G14 -> -40000
B15: CMV papier | F15: =-1*100000 -> -100000 | G15: =-1*80000 -> -80000 | H15: =-70000*1 -> -70000
B16: CMV aluminum | G16: =-('Recyclage-MCV'!J6+'Recyclage-MCV'!J7)*'Recyclage-MCV'!J14 -> -33780000
B17: CMV Plastique | H17: =-30000*(250+520*0.3) -> -12180000
B18: CMV total | F18: =+SUM(F13:F17) -> -4040000 | G18: =+SUM(G13:G17) -> -37800000 | H18: =+SUM(H13:H17) -> -16190000
B19: MCV total | F19: =+F7+F18 -> 3686000 | G19: =+G7+G18 -> 10504000 | H19: =+H7+H18 -> 7103000
B20: Cout de Main d'œuvre (augmentation selon le taux d'inflation) | F20: =-1700000*1.02 -> -1734000 | G20: =-1700000*1.02 -> -1734000 | H20: =+G20 -> -1734000
B21: Amortissement | F21: -365000 | G21: -365000 | H21: =+G21 -> -365000
B22: Autres couts d'exploitaition (augmentation 1%) | F22: =-815000*1.01 -> -823150 | G22: =+F22 -> -823150 | H22: =+G22 -> -823150
B23: Cout d'expoitation supplementaires minimaux | G23: -270000 | H23: =+G23 -> -270000
B24: Coûts d’exploitation différentiels Aluminium | G24: =-'Recyclage - VAN'!D9 -> -850000
B25: Coûts d’exploitation différentiels plastique | H25: =-'Recyclage - VAN'!D26 -> -540000
B26: Amortissment matariel aluminium | G26: ='Recyclage - VAN'!C15/10 -> -2000000 | J26: Durée de vie | K26: 10 ans
B27: Amortissement matériel plastique | H27: =+'Recyclage - VAN'!C33/10 -> -1000000
B28: Bénifice d'exploitation | F28: =+SUM(F19:F27) -> 763850 | G28: =+SUM(G19:G27) -> 4461850 | H28: =+SUM(H19:H27) -> 2370850 | J28: Pour 2022
B29: Impots | C29: 0.265 | F29: =-F28*$C29 -> -202420.25 | G29: =-G28*$C29 -> -1182390.2 | H29: =-H28*$C29 -> -628275.25
B30: Bénéfice net | F30: =+SUM(F28:F29) -> 561429.75 | G30: =+SUM(G28:G29) -> 3279459.8 | H30: =+SUM(H28:H29) -> 1742574.8

Sheet Recyclage - VAN
A1: Option 3 : Usines de recyclage - Analyse de l'investissement
A3: Objectif : Calculer la VAN du recyclage de l’aluminium et des plastiques PET, et les flux de trésorerie disponibles connexes.
C5: 2021 | D5: 2022 | E5: 2023 | F5: 2024 | G5: 2025 | H5: 2026 | I5: 2027 | J5: 2028 | K5: 2029 | L5: 2030 | M5: 2031
B6: Flux de trésorerie d’exploitation nets liés à l’aluminium
B8: Total de la marge sur coûts variables | D8: 6820000 | E8: =D8 -> 6820000 | F8: =E8 -> 6820000 | G8: =F8 -> 6820000 | H8: =G8 -> 6820000 | I8: =H8 -> 6820000 | J8: =I8 -> 6820000 | K8: =J8 -> 6820000 | L8: =K8 -> 6820000 | M8: =L8 -> 6820000
B9: Coûts d’exploitation différentiels, augmentant au taux de 2 % | D9: 850000 | E9: =ROUND(D9*1.02,0) -> 867000 | F9: =ROUND(E9*1.02,0) -> 884340 | G9: =ROUND(F9*1.02,0) -> 902027 | H9: =ROUND(G9*1.02,0) -> 920068 | I9: =ROUND(H9*1.02,0) -> 938469 | J9: =ROUND(I9*1.02,0) -> 957238 | K9: =ROUND(J9*1.02,0) -> 976383 | L9: =ROUND(K9*1.02,0) -> 995911 | M9: =ROUND(L9*1.02,0) -> 1015829
B10: Flux de trésorerie d’exploitation différentiels avant impôts | D10: =+D8-D9 -> 5970000 | E10: =+E8-E9 -> 5953000 | F10: =+F8-F9 -> 5935660 | G10: =+G8-G9 -> 5917973 | H10: =+H8-H9 -> 5899932 | I10: =+I8-I9 -> 5881531 | J10: =+J8-J9 -> 5862762 | K10: =+K8-K9 -> 5843617 | ... M10: =+M8-M9 -> 5804171
B11: Impôts sur les bénéfices – 26,5 % | D11: =ROUND(+D10*0.265,0) -> 1582050 | E11: =ROUND(+E10*0.265,0) -> 1577545 | F11: =ROUND(+F10*0.265,0) -> 1572950 | G11: =ROUND(+G10*0.265,0) -> 1568263 | H11: =ROUND(+H10*0.265,0) -> 1563482 | I11: =ROUND(+I10*0.265,0) -> 1558606 | J11: =ROUND(+J10*0.265,0) -> 1553632 | K11: =ROUND(+K10*0.265,0) -> 1548559 | ... M11: =ROUND(+M10*0.265,0) -> 1538105
B12: Flux de trésorerie d’exploitation nets différentiels après impôts | D12: =+D10-D11 -> 4387950 | E12: =+E10-E11 -> 4375455 | F12: =+F10-F11 -> 4362710 | G12: =+G10-G11 -> 4349710 | H12: =+H10-H11 -> 4336450 | I12: =+I10-I11 -> 4322925 | J12: =+J10-J11 -> 4309130 | K12: =+K10-K11 -> 4295058 | ... M12: =+M10-M11 -> 4266066
B13: Valeur actualisée | C13: =NPV(0.15, D12:M12) -> 21799870
B15: Investissement | C15: -20000000
B17: Économie d’impôts | C17: =-C15*0.265 -> 5300000
B19: Valeur actualisée nette du recyclage d’aluminium | C19: =SUM(C13:C18) -> 7099870
C22: 2021 | D22: 2022 | E22: 2023 | F22: 2024 | G22: 2025 | H22: 2026 | I22: 2027 | J22: 2028 | K22: 2029 | L22: 2030 | M22: 2031
B23: Flux de trésorerie d’exploitation nets liés aux plastiques PET
B25: Total de la marge sur coûts variables | D25: 3420000 | E25: =D25 -> 3420000 | F25: =E25 -> 3420000 | G25: =F25 -> 3420000 | H25: =G25 -> 3420000 | I25: =H25 -> 3420000 | J25: =I25 -> 3420000 | K25: =J25 -> 3420000 | L25: =K25 -> 3420000 | M25: =L25 -> 3420000
B26: Coûts d’exploitation différentiels, augmentant au taux de 2 % | D26: 540000 | E26: =ROUND(D26*1.02,0) -> 550800 | F26: =ROUND(E26*1.02,0) -> 561816 | G26: =ROUND(F26*1.02,0) -> 573052 | H26: =ROUND(G26*1.02,0) -> 584513 | I26: =ROUND(H26*1.02,0) -> 596203 | J26: =ROUND(I26*1.02,0) -> 608127 | K26: =ROUND(J26*1.02,0) -> 620290 | L26: =ROUND(K26*1.02,0) -> 632696 | M26: =ROUND(L26*1.02,0) -> 645350
B27: Flux de trésorerie d’exploitation différentiels avant impôts | D27: =+D25-D26 -> 2880000 | E27: =+E25-E26 -> 2869200 | F27: =+F25-F26 -> 2858184 | G27: =+G25-G26 -> 2846948 | H27: =+H25-H26 -> 2835487 | I27: =+I25-I26 -> 2823797 | J27: =+J25-J26 -> 2811873 | K27: =+K25-K26 -> 2799710 | ... M27: =+M25-M26 -> 2774650
B28: Impôts sur les bénéfices – 26,5 % | D28: =+D27*0.265 -> 763200 | E28: =ROUND(+E27*0.265,0) -> 760338 | F28: =ROUND(+F27*0.265,0) -> 757419 | G28: =ROUND(+G27*0.265,0) -> 754441 | H28: =ROUND(+H27*0.265,0) -> 751404 | I28: =ROUND(+I27*0.265,0) -> 748306 | J28: =ROUND(+J27*0.265,0) -> 745146 | K28: =ROUND(+K27*0.265,0) -> 741923 | L28: =ROUND(+L27*0.265,0) -> 738636 | M28: =ROUND(+M27*0.265,0) -> 735282
B29: Flux de trésorerie d’exploitation nets différentiels après impôts | D29: =+D27-D28 -> 2116800 | E29: =+E27-E28 -> 2108862 | F29: =+F27-F28 -> 2100765 | G29: =+G27-G28 -> 2092507 | H29: =+H27-H28 -> 2084083 | I29: =+I27-I28 -> 2075491 | J29: =+J27-J28 -> 2066727 | K29: =+K27-K28 -> 2057787 | ... M29: =+M27-M28 -> 2039368
B31: Valeur actualisée | C31: =NPV(0.15,(D29:M29)) -> 10482546
B33: Investissement | C33: -10000000
B35: Économie d’impôts | C35: =-C33*0.265 -> 2650000
B37: Valeur actualisée nette du recyclage de plastiques PET | C37: =SUM(C31:C35) -> 3132546

Sheet Pristine Patrimoniale
A1: Option 4 : Évaluation de Pristine - Approche patrimoniale
A3: Objectif : Calculer la valeur de Pristine selon l’approche patrimoniale.
B6: Notes | C6: Valeur comptable | D6: Ajustement à la JVM | E6: JVM
A7: Trésorerie | C7: 5000 | D7: 0 | E7: =SUM(C7:D7) -> 5000
A8: Créances clients, montant net | C8: 1095000 | D8: 0 | E8: =SUM(C8:D8) -> 1095000
A9: Titres négociables | C9: 1050000 | D9: 150000 | E9: =SUM(C9:D9) -> 1200000
A10: Frais payés d’avance | C10: 60000 | D10: 0 | E10: =SUM(C10:D10) -> 60000
A11: Impôts latents / frais de vente | B11: Note 1 | C11: 0 | D11: =-M37 -> -82080 | E11: =SUM(C11:D11) -> -82080
C12: =SUM(C7:C11) -> 2210000 | D12: =SUM(D7:D11) -> 67920 | E12: =SUM(E7:E11) -> 2277920
A14: Immobilisations corporelles (net) | C14: 6448000 | D14: 402000 | E14: =SUM(C14:D14) -> 6850000
A15: R-D en cours | C15: 0 | D15: 800000 | E15: =SUM(C15:D15) -> 800000 | F15: Donnée fournie
A16: Impôts latents / frais de vente | B16: Note 1 | C16: 0 | D16: =-M35 -> -500115 | E16: =SUM(C16:D16) -> -500115
C17: =SUM(C12:C16) -> 8658000 | D17: =SUM(D12:D16) -> 769805 | E17: =SUM(E12:E16) -> 9427805 | F17: WDI n’a pas l’option d’acheter les actifs si elle décide de renoncer à l’achat des actions; il n’est donc pas nécessaire que l’analyse tienne compte d’un coût de renonciation lié à l’achat des actifs.
A19: Fournisseurs | C19: -241000 | D19: 0 | E19: =SUM(C19:D19) -> -241000
A20: Impôts à payer | C20: -70000 | D20: 0 | E20: =SUM(C20:D20) -> -70000
A21: Actif net | C21: =SUM(C17:C20) -> 8347000 | D21: =SUM(D17:D20) -> 769805 | E21: =SUM(E17:E20) -> 9116805
A26: Note 1: Calcul des impôts latents et des frais de vente pour les titres négociables et les immobilisations corporelles
B28: JVM (Ann. VIII) | C28: Frais de vente @ 5 % (Ann. VIII) | D28: Produit net | E28: PBR (Ann. VIII) | F28: Gain (perte) en capital | G28: Gain (perte) imposable | H28: Impôts estimés @ 24 %* | I28: Plus faible du prix et du produit | J28: FNACC (Ann. VIII) | K28: Récupération / (perte finale) | L28: Impôts estimés @ 26,5 % | M28: Impôts latents et frais de vente
B29: A | C29: B | D29: C = A - B | E29: D | F29: E = C - D | G29: F = E × 50 % | H29: G = F × 24 % | I29: H | J29: I | K29: J = H - I | L29: K = J × 26,5 % | M29: L = B + G + K
A31: Immobilisations corporelles
A32: Terrain | B32: 580000 | C32: =0.05*B32 -> 29000 | D32: =B32-C32 -> 551000 | E32: 310000 | F32: =D32-E32 -> 241000 | G32: =0.5*F32 -> 120500 | H32: =G32*0.24 -> 28920 | I32: Aucune récupération / perte finale sur le terrain | M32: =C32+H32 -> 57920
A33: Bâtiment | B33: 1710000 | C33: =0.05*B33 -> 85500 | D33: =B33-C33 -> 1624500 | E33: 1230000 | F33: =D33-E33 -> 394500 | G33: =0.5*F33 -> 197250 | H33: =G33*0.24 -> 47340 | I33: =MIN(E33,D33) -> 1230000 | J33: 1195000 | K33: =I33-J33 -> 35000 | L33: =K33*0.265 -> 9275 | M33: =C33+H33+L33 -> 142115
A34: Matériel | B34: 4560000 | C34: =0.05*B34 -> 228000 | D34: =B34-C34 -> 4332000 | E34: 6240000 | F34: Pas de perte en capital sur des immobilisations amortissables | I34: =MIN(F34,D34) -> 4332000 | J34: 4060000 | K34: =I34-J34 -> 272000 | L34: =K34*0.265 -> 72080 | M34: =C34+H34+L34 -> 300080
B35: =SUM(B32:B34) -> 6850000 | J35: =SUM(J33:J34) -> 5255000 | L35: Total des immobilisations corporelles | M35: =SUM(M32:M34) -> 500115 | N35: [5]
A37: Titres négociables | B37: 1200000 | C37: =0.05*B37 -> 60000 | D37: =B37-C37 -> 1140000 | E37: 956000 | F37: =D37-E37 -> 184000 | G37: =0.5*F37 -> 92000 | H37: =G37*0.24 -> 22080 | I37: Aucune récupération / perte finale sur les titres négociables | M37: =H37+C37 -> 82080 | N37: [2]
A39: * Suppose que des dividendes suffisants sont versés pour obtenir un remboursement complet dans le compte de l’IMRTD (54 2/3 % - 30 2/3 % = 24 %).

Sheet Pristine - capitalisation 
A1: Option 4 : Évaluation de Pristine Méthode de la capitalisation des flux
A3: 1. Normalisation du BAIIA
C4: 2020 | D4: 2019 | E4: 2018
A5: Bénéfice avant impôts | C5: 2350000 | D5: 1490000 | E5: 1020000
A7: Éléments de normalisation :
A8: Salaires – propriétaire (réel) | C8: 0 | D8: 100000 | E8: 100000 | F8: Augmentation des flux de trésorerie de 100 000$, car un poste similaire à celui de Connie est normalement rémunéré 400 000$ dans des sociétés comparables.
A9: Loyers inférieurs aux taux du marché | C9: -125000 | D9: -125000 | E9: -125000 | F9: Diminution des flux de trésorerie de 125 000$, afin que les flux de trésorerie tiennent compte des tarifs en vigueur sur le marché.
A10: Bénéfice normalisé avant impôts | C10: =SUM(C5:C9) -> 2225000 | D10: =SUM(D5:D9) -> 1465000 | E10: =SUM(E5:E9) -> 995000
A11: Produits d’intérêts découlant des actifs excédentaires – titres négociables | C11: -40000 | D11: -30000 | E11: -25000 | F11: Les titres négociables constituent des actifs excédentaires; les produits d’intérêts connexes doivent donc être éliminés.
A12: Amortissement | C12: 520000 | D12: 500000 | E12: 480000
A13: BAIIA normalisé | C13: =SUM(C10:C12) -> 2705000 | D13: =SUM(D10:D12) -> 1935000 | E13: =SUM(E10:E12) -> 1450000
C15: Bas : Moyenne de 2018 à 2020 | D15: Haut : Montant de 2020
A16: Fourchette de BAIIA sélectionnée | C16: =AVERAGE(C13:E13) -> 2030000 | D16: =C13 -> 2705000
A19: 2. Tableau de capitalisation
D20: Bas | E20: Haut
A21: Fourchette de BAIIA choisie | D21: =C16 -> 2030000 | E21: =D16 -> 2705000
A22: Impôts sur les bénéfices (26,5 %) | D22: =-0.265*D21 -> -537950 | E22: =-0.265*E21 -> -716825
A23: Flux de trésorerie normalisés après impôts | D23: =SUM(D21:D22) -> 1492050 | E23: =SUM(E21:E22) -> 1988175
A25: Réinvestissement de maintien, déduction faite de l'économie d’impôts | C25: note 1 | D25: =-C58 -> -587086.96 | E25: =-D58 -> -589837.16
A26: Flux de trésorerie discrétionnaires disponibles prévisibles normalisés | D26: =SUM(D23:D25) -> 904963.04 | E26: =SUM(E23:E25) -> 1398337.8
A28: 3. Flux de trésorerie discrétionnaire capitalisés
A29: CMPC – Taux de capitalisation | D29: 0.15 | E29: 0.16
A30: Multiple de capitalisation, arrondi à deux décimales | D30: =ROUND(1/D29,2) -> 6.67 | E30: =ROUND(1/E29,2) -> 6.25
A31: Flux de trésorerie discrétionnaires capitalisés | D31: =D30*D26 -> 6036103.5 | E31: =E30*E26 -> 8739611.5
A33: 4. Valeur capitalisée des activités
A34: VA de l'économie d’impôts liée à la FNACC des actifs existants | C34: note 2 | D34: =C80 -> 681468.42 | E34: =+D80 -> 661057.22
A35: Valeur capitalisée des activités | D35: =SUM(D31:D34) -> 6717571.9 | E35: =SUM(E31:E34) -> 9400668.7
A37: 5. Valeur des actifs excédentaires
A38: Ajouter la valeur des actifs excédentaires :
A39: Titres négociables | C39: Voir analyse approche patrimoniale | D39: 1117920 | E39: =D39 -> 1117920
A41: Valeur de l’entreprise | D41: =D35+D39 -> 7835491.9 | E41: =E35+E39 -> 10518589
A43: 6. Emprunts portants intérpet
A44: Moins : Encours des emprunts portant intérêt | D44: 0 | E44: 0
A46: Valeur des capitaux propres | D46: =D41-D44 -> 7835491.9 | E46: =E41-E44 -> 10518589
A49: Notes supplémentaires :
A50: Note 1
A51: Économie d’impôts liée au matériel
B52: Coût initial | C52: 700000 | D52: 700000
B53: DPA | C53: 0.2 | D53: 0.2
B54: Taux d’imposition | C54: 0.265 | D54: 0.265
...
