Workbook

Sheet 1.1 EGI
D2: Electronic Games inc.
D3: Bilan (en milliers)
D4: 31 décembre 2025 | E4: 31 décembre 2024
A5: ACTIF COURT TERME
B6: Trésorerie | D6: 1511 | E6: 4193
B7: Placements | C7: Note 1 | D7: 700 | E7: 514
B8: Dividende à recevoir - PI | D8: 9
B9: Impôt et subventions à recevoir | D9: 1291 | E9: 1100
B10: Effet à recevoir | D10: 15 | E10: 0
B11: Stocks | D11: 300 | E11: 245
B12: Frais payés d'avance | D12: 100 | E12: 110
D13: =SUM(D6:D12) -> 3926 | E13: =SUM(E6:E12) -> 6162
A14: ACTIF LONG TERME
B15: Immobilisation louée | D15: 833 | E15: 1046
B16: Actifs incorporels | D16: 2100 | E16: 1900
B17: Placements | C17: Note 2 | D17: =D52 -> 2900 | E17: 0
D18: =SUM(D15:D17) -> 5833 | E18: =SUM(E15:E17) -> 2946
D20: =D18+D13 -> 9759 | E20: =E18+E13 -> 9108
A22: PASSIF COURT TERME
B23: Fournisseurs | D23: 75 | E23: 79
B24: Salaires à payer | D24: 215 | E24: 191
B25: Portion court terme de l'emprunt long-terme | D25: 500 | E25: 500
D26: =SUM(D23:D25) -> 790 | E26: =SUM(E23:E25) -> 770
A27: PASSIF LONG TERME
B28: Obligations locatives | D28: 915 | E28: 1045
B29: Passif d'impôts futurs | D29: 214 | E29: 193
B30: Emprunt long-terme | D30: 3500 | E30: 4000
B31: Moins : portion court terme | D31: -500 | E31: -500
D32: =SUM(D28:D31) -> 4129 | E32: =SUM(E28:E31) -> 4738
D34: =D32+D26 -> 4919 | E34: =E32+E26 -> 5508
A36: CAPITAUX PROPRES
B37: Capital-actions ordinaire | D37: 500 | E37: 500
B38: Bénéfices non répartis | D38: 4340 | E38: 3100
D39: =SUM(D37:D38) -> 4840 | E39: =SUM(E37:E38) -> 3600
D41: =D39+D34 -> 9759 | E41: =E39+E34 -> 9108
D43: =D20-D39-D34 -> 0 | E43: =E20-E39-E34 -> 0
B45: =C7 -> Note 1
B46: Il s'agit de titres boursiers, principalement constitués d'actions de diverses entreprises.
B48: =C17 -> Note 2
B49: Les placements, en date du 1er janvier 2025, sont constitués de :
...

Sheet 1.2 PI
D2: Pintendo inc.
D3: Bilan (en milliers)
D4: 31 décembre 2025 | E4: 1er janvier 2025
D5: Valeur comptable | E5: Valeur comptable | F5: Juste valeur
A6: ACTIF COURT TERME
B7: Trésorerie | D7: 319 | E7: 48 | F7: 48
B8: Impôt et subventions à recevoir | D8: 167 | E8: 90 | F8: 90
B9: Stocks | C9: Note 1 | D9: 76 | E9: 250 | F9: 250
B10: Frais payés d'avance | D10: 45 | E10: 20 | F10: 20
D11: =SUM(D7:D10) -> 607 | E11: =SUM(E7:E10) -> 408 | F11: =SUM(F7:F10) -> 408
A12: ACTIF LONG TERME
B13: Actif d'impôts futurs | D13: 4 | E13: 43 | F13: 43
B14: Immobilistions corporelles | C14: Note 2 | D14: 13 | E14: 17 | F14: 14
B15: Actifs incorporels | C15: Note 3 | D15: 228 | E15: 312 | F15: 775
D16: =SUM(D13:D15) -> 245 | E16: =SUM(E13:E15) -> 372 | F16: =SUM(F13:F15) -> 832
B18: Actif | D18: =D16+D11 -> 852 | E18: =E16+E11 -> 780 | F18: =F16+F11 -> 1240
A20: PASSIF COURT TERME
B21: Fournisseurs | D21: 12 | E21: 45 | F21: 45
B22: Salaires à payer | D22: 17 | E22: 14 | F22: 14
B23: Dividende à payer | D23: 50
B24: Portion court terme de l'emprunt long-terme | D24: 120 | E24: 100 | F24: 100
D25: =SUM(D21:D24) -> 199 | E25: =SUM(E21:E24) -> 159 | F25: =SUM(F21:F24) -> 159
A26: PASSIF LONG TERME
B27: Emprunt long-terme | D27: 350 | E27: 350 | F27: 350
B28: Moins : portion court terme | D28: -120 | E28: -100 | F28: -100
D29: =SUM(D27:D28) -> 230 | E29: =SUM(E27:E28) -> 250 | F29: =SUM(F27:F28) -> 250
D31: =D29+D25 -> 429 | E31: =E29+E25 -> 409 | F31: =F29+F25 -> 409
A33: CAPITAUX PROPRES
B34: Capital-actions ordinaire | D34: 110 | E34: 110
B35: Bénéfices non répartis | C35: Note 4 | D35: 313 | E35: 261
D36: =SUM(D34:D35) -> 423 | E36: =SUM(E34:E35) -> 371
D38: =D36+D31 -> 852 | E38: =E36+E31 -> 780
D39: =D18-D36-D31 -> 0 | E39: =E18-E36-E31 -> 0
B42: =C9 -> Note 1
B43: Les stocks de PI sont évalués au coût. Étant donné la popularité des jeux de PI, le délai d'écoulement des stocks est de 34 jours seulement.
B46: =C14 -> Note 2
B47: Les actifs corporels de PI se détaillent comme suit :
D48: 31 décembre 2025 | E48: 1er janvier 2025
D49: Valeur comptable | F49: Valeur comptable | H49: Juste valeur | I49: Durée de vie
C50: Ordinateurs | D50: =F50 -> 12 | F50: 12 | H50: 8 | I50: 4
...

Sheet 1.3 EAI
D2: Epic Arts inc.
D3: Bilan (en milliers)
D4: 31 décembre 2025 | E4: 1er janvier 2025
D5: Valeur comptable | E5: Valeur comptable | F5: Juste valeur
A6: ACTIF COURT TERME
B7: Trésorerie | D7: 488 | E7: 350 | F7: 350
B8: Impôt et subventions à recevoir | D8: 215 | E8: 209 | F8: 209
B9: Frais payés d'avance | C9: Note 1 | D9: 12 | E9: 20 | F9: 25
D10: =SUM(D7:D9) -> 715 | E10: =SUM(E7:E9) -> 579 | F10: =SUM(F7:F9) -> 584
A11: ACTIF LONG TERME
B12: Actif d'impôts futurs | C12: Note 2 | D12: 0 | E12: 15 | F12: 17
B13: Immobilisations corporelles | C13: Note 3 | D13: 18 | E13: 30 | F13: 25
B14: Actifs incorporels | C14: Note 4 | D14: 500 | E14: 600 | F14: 2400
D15: =SUM(D12:D14) -> 518 | E15: =SUM(E12:E14) -> 645 | F15: =SUM(F12:F14) -> 2442
D17: =D15+D10 -> 1233 | E17: =E15+E10 -> 1224 | F17: =F15+F10 -> 3026
A19: PASSIF COURT TERME
B20: Fournisseurs | D20: 355 | E20: 310 | F20: 310
B21: Salaires et boni à payer | D21: 135 | E21: 29 | F21: 29
B22: Effet à payer | D22: 15
B23: Portion court terme de l'emprunt long-terme | D23: 40 | E23: 40 | F23: 40
D24: =SUM(D20:D23) -> 545 | E24: =SUM(E20:E23) -> 379 | F24: =SUM(F20:F23) -> 379
A25: PASSIF LONG TERME
B26: Passif d'impôts futurs | C26: Note 2 | D26: 22 | E26: 0 | F26: 0
B27: Emprunt long-terme | C27: Note 5 | D27: 400 | E27: 440 | F27: 444
B28: Moins : portion court terme | D28: -40 | E28: -40 | F28: -40
D29: =SUM(D26:D28) -> 382 | E29: =SUM(E27:E28) -> 400 | F29: =SUM(F27:F28) -> 404
D31: =D29+D24 -> 927 | E31: =E29+E24 -> 779 | F31: =F29+F24 -> 783
A33: CAPITAUX PROPRES
B34: Capital-actions ordinaire | D34: 170 | E34: 170
B35: Bénéfices non répartis | D35: 136 | E35: 275
D36: =SUM(D34:D35) -> 306 | E36: =SUM(E34:E35) -> 445
D38: =D36+D31 -> 1233 | E38: =E36+E31 -> 1224
D40: =D17-D36-D31 -> 0 | E40: =E17-E36-E31 -> 0
B42: =C9 -> Note 1
B43: Les frais payés d'avance au 1er janvier 2025 correspondent à un accès à un logiciel pour les graphistes pour 18 mois, soit du 1er janvier 2025 au 30 juin 2026. En date du 1er janvier 2025, soit après qu’EAI ait signé son entente, le prix pour la même licence avait été augmenté par le fournisseur en question.
B48: =C12 -> Note 2
B49: En date du 1er janvier 2025, EAI avait un actif d'impôts différés, principalement grâce aux pertes fiscales encore partiellement inutilisées. En date du 31 décembre 2025, grâce à l'acquisition d'EAI par EGI, les pertes ont finalement pu être utilisées
B54: =C13 -> Note 3
B55: Les actifs corporels d'EAI se détaillent comme suit :
D56: 31 décembre 2025 | E56: 1er janvier 2025
...

Sheet A.2) Regroupement
A1: Cas Electronic Games inc.
A2: Analyse à la date de regroupement | D2: 1er janvier 2025
A4: Il s'agit d'une suggestion de solution qui suit la structure vue dans le cadre du cours de Regroupement au BAA.
C6: Contrepartie transférée | D6: =+D29 -> 3180.812 | E6: Note 1
C7: Moins :
C8: Valeur comptable d'EAI | D8: ='1.3 EAI'!E36 -> 445
C9: Premier écart de consolidation | D9: =D6-D8 -> 2735.812
C11: Frais payés d'avance | D11: =-'1.3 EAI'!F9+'1.3 EAI'!E9 -> -5
C12: Actif d'impôts futurs | D12: =-'1.3 EAI'!F12+'1.3 EAI'!E12 -> -2
C13: Actifs corporels | D13: =-'1.3 EAI'!F13+'1.3 EAI'!E13 -> 5
C14: Actifs incorporels | D14: =-'1.3 EAI'!F14+'1.3 EAI'!E14 -> -1800
C15: Bail à conditions avantageuses | D15: =-D35 -> -870.9876 | E15: Note 2
C17: Emprunt long-terme | D17: =+D40 -> 4.3864619
C18: Passif éventuel | D18: =+F50 -> 343.75 | E18: Note 3
C19: Passif d'impôts futurs résultant des réévaluations | D19: =D57 -> 697.45534 | E19: Note 4
C20: Écart d'acquisition | D20: =SUM(D9:D19) -> 1108.4162
C21: N.B. : l'écart d'acquisition sera présent dans les états financiers consolidés d'EGI.
C25: =+E6 -> Note 1
C26: Contrepartie versée | D26: 2500
C27: Salaire | D27: 0 | F27: non lié à la vente des actions
C28: "Rémunération" additionnelle de 250 k$/an pendant 3 ans | D28: =+G30 -> 680.81201 | G28: 1 | H28: 2 | I28: 3
D29: =SUM(D26:D28) -> 3180.812 | G29: 250 | H29: 250 | I29: 250
F30: 0.05 | G30: =NPV(F30,G29:I29) -> 680.81201
C32: =E15 -> Note 2
C33: Valeur actualisée des paiements selon le bail | D33: =PV(5%/12,4*12,-80,0,1) -> 3488.3108 | E33: N = 48 (car reste 4 ans au bail de 5 ans, qui a commencé le 1er janvier 2024) ; i = 5% (car taux d'emprunt d'EAI) ; PMT = 80
C34: Valeur actualisée des paiements selon la juste valeur | D34: =PV(5%/12,4*12,-0.215*465,0,1) -> 4359.2984 | E34: N = 48 (car reste 4 ans au bail de 5 ans, qui a commencé le 1er janvier 2024) ; i = 5% (car taux d'emprunt d'EAI) ; PMT = 100 $ (car 465 mètres carrés * 215$/mètre carré)
C35: Immobilisation incorporelle | D35: =D34-D33 -> 870.9876
C38: Juste valeur de la dette, taux marché 5% | D38: =+G43 -> 444.38646 | G38: 45658 | H38: 46022 | I38: 46387 | J38: 46752 | K38: 47118 | L38: 47483 | M38: 47848
C39: Valeur comptable de la dette | D39: =+G39 -> 440 | G39: 440
D40: =D38-D39 -> 4.3864619 | F40: capital | H40: 40 | I40: 40 | J40: 40 | K40: 40 | L40: 40 | M40: =G39-SUM(H40:L40) -> 240
E41: 0.0525 | F41: intérêts | H41: =+G39*E41 -> 23.1 | I41: =+($G39-(SUM($H40:H40)))*$E41 -> 21 | J41: =+($G39-(SUM($H40:I40)))*$E41 -> 18.9 | K41: =+($G39-(SUM($H40:J40)))*$E41 -> 16.8 | L41: =+($G39-(SUM($H40:K40)))*$E41 -> 14.7 | M41: =+($G39-(SUM($H40:L40)))*$E41 -> 12.6
H42: =SUM(H40:H41) -> 63.1 | I42: =SUM(I40:I41) -> 61 | J42: =SUM(J40:J41) -> 58.9 | K42: =SUM(K40:K41) -> 56.8 | L42: =SUM(L40:L41) -> 54.7 | M42: =SUM(M40:M41) -> 252.6
F43: 0.05 | G43: =NPV(F43,H42:M42) -> 444.38646
C45: =+E18 -> Note 3
C46: à la juste valeur
D47: Probabilité | E47: $
C48: Scénario : gagne la cause | D48: 0.45 | E48: 0 | F48: =+D48*E48 -> 0
C49: Scénario : perd la cause | D49: 0.55 | E49: =(500+750)/2 -> 625 | F49: =+D49*E49 -> 343.75
F50: =SUM(F48:F49) -> 343.75
C52: Note 4 | E52: objectif est de faire un calcul ultra rapide
...

Sheet A.3) Placement avec influence
A1: Cas Electronic Games inc.
B3: Méthode de la comptabilisation à la valeur de consolidation
C4: Déterminer le revenu de participation en date du 30 avril 2022
C5: Revenu de participation
C6: Quote-part du bénéfice net | D6: =17%*'1.2 PI'!D72 -> 17.34
C7: Quote-part de l'amortissement | D7: =-H18 -> -21.604167 | E7: Note 1
C8: Revenu (perte) de participation | D8: =SUM(D6:D7) -> -4.2641667
C10: =E7 -> Note 1
D11: Juste valeur | E11: Valeur comptable | F11: Plus-value (moins-value) | G11: Durée de vie résiduelle | H11: Matérialisation 2025
C12: Ordinateurs | D12: =+'1.2 PI'!H50 -> 8 | E12: =+'1.2 PI'!F50+'1.2 PI'!F51 -> 9 | F12: =D12-E12 -> -1 | G12: 3 | H12: =F12/G12 -> -0.33333333
C13: Mobilier de bureau | D13: =+'1.2 PI'!H52 -> 6 | E13: =+'1.2 PI'!F52+'1.2 PI'!F53 -> 8 | F13: =D13-E13 -> -2 | G13: 8 | H13: =F13/G13 -> -0.25
C14: Logiciels achetés ou développés à l'interne | D14: =+'1.2 PI'!H61 -> 215 | E14: =+'1.2 PI'!F61+'1.2 PI'!F62 -> 72 | F14: =D14-E14 -> 143 | G14: 3 | H14: =F14/G14 -> 47.666667
C15: Jeux vidéo développés à l'interne | D15: =+'1.2 PI'!H63 -> 560 | E15: =+'1.2 PI'!F63+'1.2 PI'!F64 -> 240 | F15: =D15-E15 -> 320 | G15: 4 | H15: =F15/G15 -> 80
G16: pour 12 mois | H16: =SUM(H12:H15) -> 127.08333
G17: quote part d'EGI | H17: 0.17
G18: amortissement à ajouter dans la valeur de consolidation | H18: =H16*H17 -> 21.604167 | I18: en réduction de la participation et du revenu de participation
C20: Coût d'acquisition | D20: 400
C21: Valeur nette :
C22: Juste valeur des actifs | D22: ='1.2 PI'!F18*17% -> 210.8 | E22: selon la quote-part détenue par EGI
C23: Juste valeur des passifs | D23: =+'1.2 PI'!E31*17% -> 69.53 | E23: selon la quote-part détenue par EGI
C24: Écart d'acquisition sur valeur de consolidation | D24: =D20-(D22-D23) -> 258.73 | E24: pas amortissable, sujet à un test de dépréciatiion
C28: Déterminer la valeur comptable de la participation dans PI en en date du 31 décembre 2025
C29: Coût d'acquisition | D29: =D20 -> 400
C30: Revenu de participation | D30: =D8 -> -4.2641667
C31: Quote-part des dividendes déclarés | D31: =--'1.2 PI'!D73*0.17 -> -8.5
C32: Participation | D32: =SUM(D29:D31) -> 387.23583
B35: États financiers individuels d'EGI en date du 31 décembre 2025
C36: Correction :
C37: Revenu - dividendes | D37: =-D31 -> 8.5
C38: Revenu de participation | D38: =-D8 -> 4.2641667
C39: @Participation - méthode de la valeur de consolidation | E39: =SUM(D37:D38) -> 12.764167

Sheet A.4) Consolidé
A1: Cas Electronic Games inc.
A2: Ce n'est pas une solution exhaustive : il s'agit seulement d'un document de support pour la partie quantitative de ce cas.
A3: Se référer aux notes pédagogiques pour les problèmes d'informations financières.
G5: Bilan au 31 décembre 2025 | I5: Ajustements | L5: Bilan au 31 décembre 2025
D6: EGI | E6: Corrections préalables | F6: Explication | G6: EGI corrigé | H6: EAI | I6: Note 2 | J6: Note 3 | K6: Note 4 | L6: EGI consolidé
B7: ACTIF COURT TERME
C8: Trésorerie | D8: 1511 | G8: =D8+E8 -> 1511 | H8: 488.5 | L8: =G8+H8+SUM(I8:K8) -> 1999.5
C9: Placements | D9: 700 | G9: =D9+E9 -> 700 | L9: =G9+H9+SUM(I9:K9) -> 700
C10: Dividende à recevoir - PI | D10: 9 | G10: =D10+E10 -> 9 | L10: =G10+H10+SUM(I10:K10) -> 9
C11: Impôt et subventions à recevoir | D11: 1291 | G11: =D11+E11 -> 1291 | H11: 215 | L11: =G11+H11+SUM(I11:K11) -> 1506
C12: Effet à recevoir | D12: 15 | G12: =D12+E12 -> 15 | K12: -15 | L12: =G12+H12+SUM(I12:K12) -> 0
C13: Stocks | D13: 300 | G13: =D13+E13 -> 300 | L13: =G13+H13+SUM(I13:K13) -> 300
C14: Frais payés d'avance | D14: 100 | G14: =D14+E14 -> 100 | H14: 12 | I14: =D59 -> 5 | J14: =-D78 -> -3.3333333 | L14: =G14+H14+SUM(I14:K14) -> 113.66667
B16: ACTIF LONG TERME
C17: Actif d'impôts futurs | I17: =D60 -> 2 | J17: =-I17 -> -2 | L17: =G17+H17+SUM(I17:K17) -> 0
C18: Immobilisation louée | D18: 833 | G18: =D18+E18 -> 833 | L18: =G18+H18+SUM(I18:K18) -> 833
C19: Immobilisations corporelles | G19: =D19+E19 -> 0 | H19: 18 | I19: -5 | J19: =-H82 -> 2.5 | L19: =G19+H19+SUM(I19:K19) -> 15.5
C20: Actifs incorporels | D20: 2100 | G20: =D20+E20 -> 2100 | H20: 500 | I20: =D61+D62 -> 2670.9876 | J20: =-H83-H84-F89 -> -707.7469 | L20: =G20+H20+SUM(I20:K20) -> 4563.2407
C21: Placements | D21: 2900 | G21: =D21+E21 -> 2900 | I21: =-E66 -> -3180.812 | L21: =G21+H21+SUM(I21:K21) -> -280.81201
C22: Écart d'acquisition | G22: =D22+E22 -> 0 | I22: =+D63 -> 1108.4162 | L22: =G22+H22+SUM(I22:K22) -> 1108.4162
B24: PASSIF COURT TERME
C25: Fournisseurs | D25: 75 | G25: =D25+E25 -> 75 | H25: 355 | L25: =G25+H25+SUM(I25:K25) -> 430
C26: Salaires à payer | D26: 215 | G26: =D26+E26 -> 215 | H26: 135 | L26: =G26+H26+SUM(I26:K26) -> 350
C27: Effet à payer | G27: =D27+E27 -> 0 | H27: 15 | K27: -15 | L27: =G27+H27+SUM(I27:K27) -> 0
C28: Passif éventuel | G28: =D28+E28 -> 0 | I28: =+E68 -> 343.75 | L28: =G28+H28+SUM(I28:K28) -> 343.75
C29: "Rémunération" additionnelle à verser | E29: =+I49 -> 250 | F29: Note 1 | G29: =D29+E29 -> 250 | L29: =G29+H29+SUM(I29:K29) -> 250
C30: Contrepartie éventuelle | G30: =D30+E30 -> 0 | L30: =G30+H30+SUM(I30:K30) -> 0
C31: Portion court terme de l'emprunt long-terme | D31: 500 | G31: =D31+E31 -> 500 | H31: 40 | L31: =G31+H31+SUM(I31:K31) -> 540
B33: PASSIF LONG TERME
C34: Obligations locatives | D34: 915 | G34: =D34+E34 -> 915 | L34: =G34+H34+SUM(I34:K34) -> 915
C35: Passif d'impôts futurs | D35: 214 | G35: =D35+E35 -> 214 | H35: 22 | I35: =+E70 -> 697.45534 | J35: =D105 -> -213.39339 | L35: =G35+H35+SUM(I35:K35) -> 720.06195
C36: "Rémunération" additionnelle à verser | E36: =+E53 -> 238.09524 | F36: Note 1 | G36: =D36+E36 -> 238.09524 | L36: =G36+H36+SUM(I36:K36) -> 238.09524
C37: Emprunt long-terme | D37: 3500 | G37: =D37+E37 -> 3500 | H37: 400 | I37: =+E69 -> 4.3864619 | J37: =-F94 -> -0.73107698 | L37: =G37+H37+SUM(I37:K37) -> 3903.6554
C38: Moins : portion court terme | D38: -500 | G38: =D38+E38 -> -500 | H38: -40 | L38: =G38+H38+SUM(I38:K38) -> -540
B40: CAPITAUX PROPRES
C41: Capital-actions ordinaire | D41: 500 | G41: =D41+E41 -> 500 | H41: 170 | I41: =-D64 -> -170 | L41: =G41+H41+SUM(I41:K41) -> 500
C42: Bénéfices non répartis | D42: 4340 | E42: =-E29-E36 -> -488.09524 | F42: Note 1 | G42: =D42+E42 -> 3851.9048 | H42: 136 | I42: =-D65 -> -275 | J42: =+SUM(J8:J22)-SUM(J25:J38) -> -496.45576 | L42: =G42+H42+SUM(I42:K42) -> 3216.449
C45: Note 1 | D45: =SUM(D8:D22)-SUM(D25:D42) -> 0 | E45: =SUM(E8:E22)-SUM(E25:E42) -> 0 | G45: =SUM(G8:G22)-SUM(G25:G42) -> 0 | H45: =SUM(H8:H22)-SUM(H25:H42) -> 0.5 | I45: =SUM(I8:I22)-SUM(I25:I42) -> 0 | J45: =SUM(J8:J22)-SUM(J25:J42) -> 0 | K45: =SUM(K8:K22)-SUM(K25:K42) -> 0 | L45: =SUM(L8:L22)-SUM(L25:L42) -> 0.5
C47: "Rémunération" additionnelle à verser
G48: =+'A.2) Regroupement'!F28 -> 0 | H48: =+'A.2) Regroupement'!G28 -> 1 | I48: =+'A.2) Regroupement'!H28 -> 2 | J48: =+'A.2) Regroupement'!I28 -> 3
...

Sheet Actifs nets
A1: Cas Electronic Games inc.
A2: Analyse à la date de regroupement | D2: 1er janvier 2025
A4: Il s'agit d'une suggestion de solution qui suit la structure vue dans le cadre du cours de Regroupement au BAA.
C6: Contrepartie transférée | D6: =+D29 -> 3180.812 | E6: Note 1
C7: Moins :
C8: Valeur comptable d'EAI | D8: ='1.3 EAI'!E36 -> 445
C9: Premier écart de consolidation | D9: =D6-D8 -> 2735.812
C11: Frais payés d'avance | D11: =-'1.3 EAI'!F9+'1.3 EAI'!E9 -> -5
C12: Actif d'impôts futurs | D12: =-'1.3 EAI'!F12+'1.3 EAI'!E12 -> -2
C13: Actifs corporels | D13: =-'1.3 EAI'!F13+'1.3 EAI'!E13 -> 5
C14: Actifs incorporels | D14: =-'1.3 EAI'!F14+'1.3 EAI'!E14 -> -1800
C15: Bail à conditions avantageuses | D15: =-D35 -> -870.9876 | E15: Note 2
C17: Emprunt long-terme | D17: =+D40 -> 4.3864619 | E17: Note 3
C18: Passif éventuel | D18: =+F50 -> 343.75 | E18: Note 4
C19: Passif d'impôts futurs résultant des réévaluations | D19: 0 | E19: Note 5
C20: Écart d'acquisition | D20: =SUM(D9:D19) -> 410.96087
C21: N.B. : l'écart d'acquisition sera présent dans les états financiers consolidés d'EGI.
C25: =+E6 -> Note 1
C26: Contrepartie versée | D26: 2500
C27: Salaire | D27: 0 | F27: non lié à la vente des actions
C28: "Rémunération" additionnelle de 250 k$/an pendant 3 ans | D28: =+G30 -> 680.81201 | G28: 1 | H28: 2 | I28: 3
D29: =SUM(D26:D28) -> 3180.812 | G29: 250 | H29: 250 | I29: 250
F30: 0.05 | G30: =NPV(F30,G29:I29) -> 680.81201
C32: =E15 -> Note 2
C33: Valeur actualisée des paiements selon le bail | D33: =PV(5%/12,4*12,-80,0,1) -> 3488.3108 | E33: N = 48 (car reste 4 ans au bail de 5 ans, qui a commencé le 1er janvier 2024) ; i = 5% (car taux d'emprunt d'EAI) ; PMT = 80
C34: Valeur actualisée des paiements selon la juste valeur | D34: =PV(5%/12,4*12,-0.215*465,0,1) -> 4359.2984 | E34: N = 48 (car reste 4 ans au bail de 5 ans, qui a commencé le 1er janvier 2024) ; i = 5% (car taux d'emprunt d'EAI) ; PMT = 100 $ (car 465 mètres carrés * 215$/mètre carré)
C35: Immobilisation incorporelle | D35: =D34-D33 -> 870.9876
C37: =+E17 -> Note 3
C38: Juste valeur de la dette, taux marché 5% | D38: =+G43 -> 444.38646 | G38: 45658 | H38: 46022 | I38: 46387 | J38: 46752 | K38: 47118 | L38: 47483 | M38: 47848
C39: Valeur comptable de la dette | D39: =+G39 -> 440 | G39: 440
D40: =D38-D39 -> 4.3864619 | F40: capital | H40: 40 | I40: 40 | J40: 40 | K40: 40 | L40: 40 | M40: =G39-SUM(H40:L40) -> 240
E41: 0.0525 | F41: intérêts | H41: =+G39*E41 -> 23.1 | I41: =+($G39-(SUM($H40:H40)))*$E41 -> 21 | J41: =+($G39-(SUM($H40:I40)))*$E41 -> 18.9 | K41: =+($G39-(SUM($H40:J40)))*$E41 -> 16.8 | L41: =+($G39-(SUM($H40:K40)))*$E41 -> 14.7 | M41: =+($G39-(SUM($H40:L40)))*$E41 -> 12.6
H42: =SUM(H40:H41) -> 63.1 | I42: =SUM(I40:I41) -> 61 | J42: =SUM(J40:J41) -> 58.9 | K42: =SUM(K40:K41) -> 56.8 | L42: =SUM(L40:L41) -> 54.7 | M42: =SUM(M40:M41) -> 252.6
F43: 0.05 | G43: =NPV(F43,H42:M42) -> 444.38646
C45: =+E18 -> Note 4
C46: à la juste valeur
D47: Probabilité | E47: $
C48: Scénario : gagne la cause | D48: 0.45 | E48: 0 | F48: =+D48*E48 -> 0
C49: Scénario : perd la cause | D49: 0.55 | E49: =(500+750)/2 -> 625 | F49: =+D49*E49 -> 343.75
F50: =SUM(F48:F49) -> 343.75
...

Sheet B) Ajustements
A1: Cas Electronic Games inc.
C5: Écart d'acquisition initial | D5: =+'A.2) Regroupement'!D20 -> 1108.4162
C6: Ajustements :
C7: Dû lié à la poursuite | D7: 750
C8: Logiciel | D8: =-D15 -> 105 | E8: diminution de la juste valeur augmente l'écart d'acquisition
C9: Boni à payer | D9: 100 | E9: augmentation du passif augmente l'écart d'acquisition
C10: Passif d'impôt futurs | D10: =-D18 -> -31.5 | E10: Note 1
D11: =SUM(D4:D10) -> 2031.9162
C14: =E10 -> Note 1
C15: Logiciel | D15: -105
C16: Différence temporaire imposable | D16: =D15 -> -105
C17: Taux d'imposition | D17: 0.3 | E17: hypothèse pour un taux combiné (tout autre taux raisonnable et justifié est acceptable)
C18: Passif d'impôt futurs | D18: =-D16*D17 -> 31.5 | E18: débiteur
