Workbook

Sheet 1.1 EGI
D2: Electronic Games inc.
D3: État de la situation financière (en milliers)
D4: 31 décembre 2025 | E4: 31 décembre 2024
A5: ACTIF COURANT
B6: Trésorerie | D6: 1511 | E6: 4193
B7: Placements | C7: Note 1 | D7: 700 | E7: 514
B8: Dividende à recevoir - PI | D8: 9
B9: Impôt et subventions à recevoir | D9: 1291 | E9: 1100
B10: Effet à recevoir | D10: 15 | E10: 0
B11: Stocks | D11: 300 | E11: 245
B12: Frais payés d'avance | D12: 100 | E12: 110
D13: =SUM(D6:D12) -> 3926 | E13: =SUM(E6:E12) -> 6162
A14: ACTIF NON COURANT
B15: Actifs au titre du droit d'utilisation | D15: 833 | E15: 1046
B16: immobilisations incorporelles | D16: 2100 | E16: 1900
B17: Placements | C17: Note 2 | D17: =D52 -> 2900 | E17: 0
D18: =SUM(D15:D17) -> 5833 | E18: =SUM(E15:E17) -> 2946
D20: =D18+D13 -> 9759 | E20: =E18+E13 -> 9108
A22: PASSIF COURANT
B23: Fournisseurs | D23: 75 | E23: 79
B24: Salaires à payer | D24: 215 | E24: 191
B25: Portion courante de l'emprunt non courant | D25: 500 | E25: 500
D26: =SUM(D23:D25) -> 790 | E26: =SUM(E23:E25) -> 770
A27: PASSIF NON COURANT
B28: Obligations locatives | D28: 915 | E28: 1045
B29: Passif d'impôts différés | D29: 214 | E29: 193
B30: Emprunt non courant | D30: 3500 | E30: 4000
B31: Moins : portion courant | D31: -500 | E31: -500
D32: =SUM(D28:D31) -> 4129 | E32: =SUM(E28:E31) -> 4738
D34: =D32+D26 -> 4919 | E34: =E32+E26 -> 5508
A36: CAPITAUX PROPRES
B37: Capital-actions ordinaire | D37: 500 | E37: 500
B38: Résultats non distribués | D38: 4340 | E38: 3100
D39: =SUM(D37:D38) -> 4840 | E39: =SUM(E37:E38) -> 3600
D41: =D39+D34 -> 9759 | E41: =E39+E34 -> 9108
D43: =D20-D39-D34 -> 0 | E43: =E20-E39-E34 -> 0
B45: =C7 -> Note 1
B46: Il s'agit de titres boursiers, principalement constitués d'actions de diverses entreprises.
B48: =C17 -> Note 2
B49: Les placements, en date du 31 décembre 2025, sont constitués de :
...

Sheet 1.2 PI
D2: Pintendo inc.
D3: État de la situation financière (en milliers)
D4: 31 décembre 2025 | E4: 1er janvier 2025
D5: Valeur comptable | E5: Valeur comptable | F5: Juste valeur
A6: ACTIF COURANT
B7: Trésorerie | D7: 319 | E7: 48 | F7: 48
B8: Impôt et subventions à recevoir | D8: 167 | E8: 90 | F8: 90
B9: Stocks | C9: Note 1 | D9: 76 | E9: 250 | F9: 250
B10: Frais payés d'avance | D10: 45 | E10: 20 | F10: 20
D11: =SUM(D7:D10) -> 607 | E11: =SUM(E7:E10) -> 408 | F11: =SUM(F7:F10) -> 408
A12: ACTIF NON COURANT
B13: Actif impôt différé | D13: 4 | E13: 43 | F13: 43
B14: Immobilistions corporelles | C14: Note 2 | D14: 13 | E14: 17 | F14: 14
B15: immobilisations incorporelles | C15: Note 3 | D15: =E64 -> 228 | E15: =G64 -> 312 | F15: 775
D16: =SUM(D13:D15) -> 245 | E16: =SUM(E13:E15) -> 372 | F16: =SUM(F13:F15) -> 832
B18: Actif | D18: =D16+D11 -> 852 | E18: =E16+E11 -> 780 | F18: =F16+F11 -> 1240
A20: PASSIF COURANT
B21: Fournisseurs | D21: 12 | E21: 45 | F21: 45
B22: Salaires à payer | D22: 17 | E22: 14 | F22: 14
B23: Dividende à payer | D23: 50
B24: Portion courante de l'emprunt | D24: 120 | E24: 100 | F24: 100
D25: =SUM(D21:D24) -> 199 | E25: =SUM(E21:E24) -> 159 | F25: =SUM(F21:F24) -> 159
A26: PASSIF NON COURANT
B27: Emprunt non courant | D27: 350 | E27: 350 | F27: 350
B28: Moins : portion courante | D28: -120 | E28: -100 | F28: -100
D29: =SUM(D27:D28) -> 230 | E29: =SUM(E27:E28) -> 250 | F29: =SUM(F27:F28) -> 250
D31: =D29+D25 -> 429 | E31: =E29+E25 -> 409 | F31: =F29+F25 -> 409
A33: CAPITAUX PROPRES
B34: Capital-actions ordinaire | D34: 110 | E34: 110
B35: Résultats non distribués | C35: Note 4 | D35: 313 | E35: 261
D36: =SUM(D34:D35) -> 423 | E36: =SUM(E34:E35) -> 371
D38: =D36+D31 -> 852 | E38: =E36+E31 -> 780
D39: =D18-D36-D31 -> 0 | E39: =E18-E36-E31 -> 0
B42: =C9 -> Note 1
B43: Les stocks de PI sont évalués au coût. Étant donné la popularité des jeux de PI, le délai d'écoulement des stocks est de 34 jours seulement.
B46: =C14 -> Note 2
B47: Les immobilisations corporelles de PI se détaillent comme suit :
D48: 31 décembre 2025 | G48: 1er janvier 2025
D49: Valeur comptable | F49: Valeur comptable | H49: Juste valeur | I49: Durée de vie
C50: Ordinateurs | D50: =F50 -> 12 | F50: 12 | H50: 8 | I50: 4
...

Sheet 1.3 EAI
D2: Epic Arts inc.
D3: Bilan (en milliers)
D4: 31 décembre 2025 | E4: 1er janvier 2025
D5: Valeur comptable | E5: Valeur comptable | F5: Juste valeur
A6: ACTIF COURANT
B7: Trésorerie | D7: 488.5 | E7: 350 | F7: 350
B8: Impôt et subventions à recevoir | D8: 215 | E8: 209 | F8: 209
B9: Frais payés d'avance | C9: Note 1 | D9: 12 | E9: 20 | F9: 25
D10: =SUM(D7:D9) -> 715.5 | E10: =SUM(E7:E9) -> 579 | F10: =SUM(F7:F9) -> 584
A11: ACTIF NON COURANT
B12: Actif d'impôts différés | C12: Note 2 | D12: 0 | E12: 15 | F12: 17
B13: Immobilisations corporelles | C13: Note 3 | D13: =E62 -> 18 | E13: 30 | F13: 25
B14: immobilisations incorporelles | C14: Note 4 | D14: =E73 -> 500 | E14: 600 | F14: 2400
D15: =SUM(D12:D14) -> 518 | E15: =SUM(E12:E14) -> 645 | F15: =SUM(F12:F14) -> 2442
D17: =D15+D10 -> 1233.5 | E17: =E15+E10 -> 1224 | F17: =F15+F10 -> 3026
A19: PASSIF COURANT
B20: Fournisseurs | D20: 355 | E20: 310 | F20: 310
B21: Salaires et boni à payer | D21: 135 | E21: 29 | F21: 29
B22: Effet à payer | D22: 15
B23: Portion court terme de l'emprunt long-terme | D23: 40 | E23: 40 | F23: 40
D24: =SUM(D20:D23) -> 545 | E24: =SUM(E20:E23) -> 379 | F24: =SUM(F20:F23) -> 379
A25: PASSIF NON COURANT
B26: Passif d'impôts différés | C26: Note 2 | D26: 22
B27: Emprunt long-terme | D27: 400 | E27: 440 | F27: 444
B28: Moins : portion court terme | D28: -40 | E28: -40 | F28: =E28 -> -40
D29: =SUM(D26:D28) -> 382 | E29: =SUM(E27:E28) -> 400 | F29: =SUM(F27:F28) -> 404
D31: =D29+D24 -> 927 | E31: =E29+E24 -> 779 | F31: =F29+F24 -> 783
A33: CAPITAUX PROPRES
B34: Capital-actions ordinaire | D34: 170 | E34: 170
B35: Résultats non distribués | D35: 136 | E35: 275
D36: =SUM(D34:D35) -> 306 | E36: =SUM(E34:E35) -> 445
D38: =D36+D31 -> 1233 | E38: =E36+E31 -> 1224
D40: =D17-D36-D31 -> 0.5 | E40: =E17-E36-E31 -> 0
B42: =C9 -> Note 1
B43: Les frais payés d'avance au 1er janvier 2025 correspondent à un accès à un logiciel pour les graphistes pour 18 mois, soit du 1er janvier 2025 au 30 juin 2026. En date du 1er janvier 2025, soit après le début de l'abonnement d'EAI, le prix pour la même licence avait été augmentée par le fournisseur en question.
B48: Note 2
B49: En date du 1er janvier 2025, EAI avait un actif d'impôts différés, principalement grâce aux pertes fiscales encore partiellement inutilisées. En date du 31 décembre 2025, grâce à l'acquisition d'EAI par EGI, les pertes ont finalement pu être utilisées.
B54: =C13 -> Note 3
B55: Les immobilisations corporelles d'EAI se détaillent comme suit :
D56: 31 décembre 2025 | E56: 1er janvier 2025 | I56: 1er janvier 2025
...

Sheet A.2) Regroupement
A1: Cas Electronic Games inc.
A2: Analyse à la date de regroupement | D2: 1er janvier 2025
A4: Il s'agit d'une suggestion de solution qui suit la structure vue dans le cadre du cours de Regroupement au BAA.
C6: Contrepartie transférée | D6: 2500
C7: Moins :
C8: Valeur comptable d'EAI | D8: ='1.3 EAI'!E36 -> 445
C9: Écart première consolidation | D9: =D6-D8 -> 2055
C11: Frais payés d'avance | D11: =-'1.3 EAI'!F9+'1.3 EAI'!E9 -> -5
C12: immobilisations corporelles | D12: =-'1.3 EAI'!F13+'1.3 EAI'!E13 -> 5
C13: immobilisations incorporelles | D13: =-'1.3 EAI'!F14+'1.3 EAI'!E14 -> -1800
C14: Emprunt long-terme | D14: 4
C15: Passif éventuel | D15: =+F26 -> 281.25 | E15: Note 1
C16: Passif d'impôts différés résultant des réévaluations | D16: =D33 -> 454.425 | E16: Note 2
C17: Goodwill | D17: =SUM(D9:D16) -> 994.675
C18: N.B. : le goodwill sera présent dans les états financiers consolidés d'EGI.
C21: =+E15 -> Note 1
C22: à la juste valeur
D23: Probabilité | E23: $
C24: Scénario : gagne la cause | D24: 0.55 | E24: 0 | F24: =+D24*E24 -> 0
C25: Scénario : perd la cause | D25: 0.45 | E25: =(500+750)/2 -> 625 | F25: =+D25*E25 -> 281.25
F26: =SUM(F24:F25) -> 281.25
C28: =E16 -> Note 2 | E28: objectif est de faire un calcul ultra rapide
C29: VC de l'actif net au 1er janvier 2025 | D29: =D8 -> 445
C30: JV de l'actif net au 1er janvier 2025 | D30: =D8-SUM(D11:D15) -> 1959.75
C31: Différence temporaire imposable | D31: =D30-D29 -> 1514.75
C32: Taux d'imposition | D32: 0.3 | E32: hypothèse pour un taux combiné (tout autre taux raisonnable et justifié est acceptable)
C33: Passif d'impôts différés | D33: =D31*D32 -> 454.425

Sheet A.3) Placement avec influence
A1: Cas Electronic Games inc.
B3: Méthode de la mise en équivalence
C4: Déterminer le revenu de participation en date du 31 décembre 2025
C5: Revenu de participation
C6: Quote-part du revenu net | D6: =17%*'1.2 PI'!D70 -> 17.34
C7: Quote-part de l'amortissement | D7: =-H18 -> -21.604167 | E7: Note 1
C8: Revenu (perte) de participation | D8: =SUM(D6:D7) -> -4.2641667
C10: =E7 -> Note 1
D11: Juste valeur | E11: Valeur comptable | F11: Plus-value (moins-value) | G11: Durée de vie résiduelle | H11: Matérialisation 2022
C12: Ordinateurs | D12: =+'1.2 PI'!H50 -> 8 | E12: =+'1.2 PI'!F50+'1.2 PI'!F51 -> 9 | F12: =D12-E12 -> -1 | G12: 3 | H12: =F12/G12 -> -0.33333333
C13: Mobilier de bureau | D13: =+'1.2 PI'!H52 -> 6 | E13: =+'1.2 PI'!F52+'1.2 PI'!F53 -> 8 | F13: =D13-E13 -> -2 | G13: 8 | H13: =F13/G13 -> -0.25
C14: Logiciels achetés ou développés à l'interne | D14: =+'1.2 PI'!H60 -> 215 | E14: =+'1.2 PI'!F60+'1.2 PI'!F61 -> 72 | F14: =D14-E14 -> 143 | G14: 3 | H14: =F14/G14 -> 47.666667
C15: Jeux vidéo développés à l'interne | D15: =+'1.2 PI'!H62 -> 560 | E15: =+'1.2 PI'!F62+'1.2 PI'!F63 -> 240 | F15: =D15-E15 -> 320 | G15: 4 | H15: =F15/G15 -> 80
G16: pour 12 mois | H16: =SUM(H12:H15) -> 127.08333
G17: quote part d'EGI | H17: 0.17
G18: amortissement à ajouter dans la valeur de consolidation | H18: =H16*H17 -> 21.604167 | I18: en réduction de la participation et du revenu de participation
C20: Coût d'acquisition | D20: 400
C21: Valeur nette :
C22: Juste valeur des actifs | D22: ='1.2 PI'!F18*17% -> 210.8 | E22: selon la quote-part détenue par EGI
C23: Juste valeur des passifs | D23: =+'1.2 PI'!F31*17% -> 69.53 | E23: selon la quote-part détenue par EGI
C24: Goodwill (inclus dans la valeur de la participation) | D24: =D20-(D22-D23) -> 258.73 | E24: pas amortissable, sujet à un test de dépréciation
C28: Déterminer la valeur comptable de la participation dans PI en en date du 31 décembre 2025
C29: Coût d'acquisition | D29: =D20 -> 400
C30: Revenu de participation | D30: =D8 -> -4.2641667
C31: Quote-part des dividendes déclarés | D31: =--'1.2 PI'!D71*0.17 -> -8.5
C32: Participation | D32: =SUM(D29:D31) -> 387.23583
B35: États financiers individuels d'EGI en date du 31 décembre 2025
C36: Correction :
C37: Revenu - dividendes | D37: =-D31 -> 8.5
C38: Revenu de participation | D38: =-D8 -> 4.2641667
C39: @Participation - méthode de la mise en équivalence | E39: =SUM(D37:D38) -> 12.764167

Sheet A.4) Consolidé
A1: Cas Electronic Games inc.
A2: Ce n'est pas une solution exhaustive : il s'agit seulement d'un document de support pour la partie quantitative de ce cas.
A3: Se référer aux notes pédagogiques pour les problèmes d'informations financières.
D5: Bilan au 31 décembre 2025 | F5: Ajustements | I5: Bilan au 31 décembre 2025
D6: EGI | E6: EAI | F6: Note 1 | G6: Note 2 | H6: Note 3 | I6: EGI consolidé
B7: ACTIF COURANT
C8: Trésorerie | D8: 1511 | E8: 488.5 | I8: =D8+E8+SUM(F8:H8) -> 1999.5
C9: Placements | D9: 700 | I9: =D9+E9+SUM(F9:H9) -> 700
C10: Dividende à recevoir - PI | D10: 9 | I10: =D10+E10+SUM(F10:H10) -> 9
C11: Impôt et subventions à recevoir | D11: 1291 | E11: 215 | I11: =D11+E11+SUM(F11:H11) -> 1506
C12: Effet à recevoir | D12: 15 | H12: -15 | I12: =D12+E12+SUM(F12:H12) -> 0
C13: Stocks | D13: 300 | I13: =D13+E13+SUM(F13:H13) -> 300
C14: Frais payés d'avance | D14: 100 | E14: 12 | F14: =D44 -> 5 | G14: =-D63 -> -3.3333333 | I14: =D14+E14+SUM(F14:H14) -> 113.66667
B16: ACTF NON COURANT
C17: Actif d'impôts différés | F17: =D45 -> 2 | G17: =-F17 -> -2 | I17: =D17+E17+SUM(F17:H17) -> 0
C18: Actifs au titre du droit d'utilisation | D18: 833 | I18: =D18+E18+SUM(F18:H18) -> 833
C19: Immobilisations corporelles | E19: ='1.3 EAI'!D13 -> 18 | F19: -5 | G19: =-H67 -> 2.5 | I19: =D19+E19+SUM(F19:H19) -> 15.5
C20: immobilisations incorporelles | D20: 2100 | E20: ='1.3 EAI'!D14 -> 500 | F20: =D46 -> 1800 | G20: =-H68-H69 -> -490 | I20: =D20+E20+SUM(F20:H20) -> 3910
C21: Placements | D21: 2900 | F21: =-E50 -> -2500 | I21: =D21+E21+SUM(F21:H21) -> 400
C22: Goodwill | F22: =+D47 -> 994.675 | I22: =D22+E22+SUM(F22:H22) -> 994.675
B24: PASSIF COURANT
C25: Fournisseurs | D25: 75 | E25: 355 | I25: =D25+E25+SUM(F25:H25) -> 430
C26: Salaires à payer | D26: 215 | E26: 135 | I26: =D26+E26+SUM(F26:H26) -> 350
C27: Effet à payer | E27: 15 | H27: -15 | I27: =D27+E27+SUM(F27:H27) -> 0
C28: Passif éventuel | F28: =+E52 -> 281.25 | I28: =D28+E28+SUM(F28:H28) -> 281.25
C29: Portion court terme de l'emprunt long-terme | D29: 500 | E29: 40 | I29: =D29+E29+SUM(F29:H29) -> 540
B31: PASSIF NON COURANT
C32: Obligations locatives | D32: 915 | I32: =D32+E32+SUM(F32:H32) -> 915
C33: Passif d'impôts différés | D33: 214 | E33: 22 | F33: 455 | G33: =D85 -> -148.05 | I33: =D33+E33+SUM(F33:H33) -> 542.95
C34: Emprunt long-terme | D34: 3500 | E34: 400 | F34: =+E54 -> 4 | G34: =-F74 -> -0.66666667 | I34: =D34+E34+SUM(F34:H34) -> 3903.3333
C35: Moins : portion court terme | D35: -500 | E35: -40 | I35: =D35+E35+SUM(F35:H35) -> -540
I36: =D36+E36+SUM(F36:H36) -> 0
B37: CAPITAUX PROPRES | I37: =D37+E37+SUM(F37:H37) -> 0
C38: Capital-actions ordinaire | D38: 500 | E38: ='1.3 EAI'!D34 -> 170 | F38: =-D48 -> -170 | I38: =D38+E38+SUM(F38:H38) -> 500
C39: Résultats non distribués | D39: ='1.1 EGI'!D38 -> 4340 | E39: ='1.3 EAI'!D35 -> 136 | F39: =-D49 -> -275 | G39: =+SUM(G8:G22)-SUM(G25:G35) -> -344.11667 | I39: =D39+E39+SUM(F39:H39) -> 3856.8833
C42: Note 1
C43: Il s'agit de la répartition du coût d'acquisition en date du 1er janvier 2025 :
C44: Frais payés d'avance | D44: ='1.3 EAI'!F9-'1.3 EAI'!E9 -> 5
C45: Actif d'impôts différés | D45: 2
C46: Immobilisations incorporelles (plus-value) | D46: ='1.3 EAI'!F14-'1.3 EAI'!E14 -> 1800
...

Sheet Actifs nets
A1: Cas Electronic Games inc.
A2: Analyse à la date de regroupement | D2: 1er janvier 2025
A4: Il s'agit d'une suggestion de solution qui suit la structure vue dans le cadre du cours de Regroupement au BAA.
C6: Contrepartie transférée | D6: 2500
C7: Moins :
C8: Valeur comptable d'EAI | D8: ='1.3 EAI'!E36 -> 445
C9: Premier écart de consolidation | D9: =D6-D8 -> 2055
C11: Frais payés d'avance | D11: =-'[1]1.3 EAI'!F9+'[1]1.3 EAI'!E9 -> -5
C12: Actif d'impôts futurs | D12: -2
C13: Actifs corporels | D13: 5
C14: Actifs incorporels | D14: -1800
C15: Emprunt long-terme | D15: =+D25 -> 4 | E15: Note 1
C16: Passif éventuel | D16: =+F32 -> 281.25 | E16: Note 2
C17: Passif d'impôts futurs résultant des réévaluations | D17: 0 | E17: Note 3
C18: Goodwill | D18: =SUM(D9:D16) -> 538.25
C19: N.B. : le goodwill sera présent dans les états financiers consolidés d'EGI.
C20: (on utilise le mot "consolidé" quand il y a regroupement d'entités juridiques)
C22: =+E15 -> Note 1
C23: Juste valeur de la dette, taux marché 5% | D23: 444
C24: Valeur comptable de la dette | D24: 440
D25: =D23-D24 -> 4
C27: =+E16 -> Note 2
C28: à la juste valeur
D29: Probabilité | E29: $
C30: Scénario : gagne la cause | D30: 0.55 | E30: 0 | F30: =+D30*E30 -> 0
C31: Scénario : perd la cause | D31: 0.45 | E31: =(500+750)/2 -> 625 | F31: =+D31*E31 -> 281.25
F32: =SUM(F30:F31) -> 281.25
C33: =E17 -> Note 3 | E33: objectif est de faire un calcul ultra rapide
C34: VC de l'actif net au 1er janvier 2022 | D34: =D8 -> 445
C35: JV de l'actif net au 1er janvier 2022 | D35: =-SUM(D11:D17)+D8 -> 1961.75
C36: Différence temporaire imposable | D36: =D35-D34 -> 1516.75
C37: Taux d'imposition | D37: 0.3 | E37: hypothèse pour un taux combiné (tout autre taux raisonnable et justifié est acceptable)
C38: Passif d'impôts différés | D38: =D36*D37 -> 455.025
C40: Dans le contexte de l'achat de l'actif net, il aurait fallu mettre à 0 $ le montant d'impôts différés présents dans les états financiers d'EAI liés aux écarts entre les bases comptables et fiscales existantes avant l'acquisition
