Workbook

Sheet Question
A1: Impôts sur le résultat
A3: Vous détenez les informations suivantes sur les états financiers préliminaires 2020 de ABC inc.
B5: Bénéfice avant impôts | G5: 500000
B7: Incluant
C8: Frais de représentation non déductibles | G8: 20000
C10: Provision pour garantie | F10: 2020 | G10: 100000
F11: 2019 | G11: 87000
C13: Provision poursuite contre ABC | F13: 2020 | G13: 50000
D14: (incident survenu en 2020)
C16: Placement dans des titres boursiers JVBRN
D17: Acquisition de 100 actions le 15 mai 2020 | G17: 45000
D18: Disposition de 25 actions le 30 sept 2020 | G18: 15000
D19: Juste valeur des 75 actions restantes au 31 déc 2020 | G19: 50000
C21: Terrain
D22: Acquis en 2017 au coût de | G22: 100000
D23: disposé le 15 mars 2020 au prix de | G23: 40000
C25: Équipement
D26: Soldes au 1er janvier 2020
E27: Valeur nette comptable | G27: 400000
E28: FNACC | G28: 300000
D29: Charge amortissement 2020 | G29: 100000
D30: Déduction pour amortissement (fiscal) | G30: 60000
B32: Pertes autres qu'en capital reportées vers l'avant | G32: 70000
C33: avantage constaté dans les états financiers 2019
B35: Taux d'impôts | F35: 2020 | G35: 0.3
F36: 2019 | G36: 0.35 | H36: Taux 2020 non connu en 2019
A38: Travail à faire
A39: Calculer les impôts exigibles et différés pour l'exercice 2020
A40: Préparer les écritures

Sheet Solution
A1: Calcul des impôts exigibles
A3: Bénéfice avant impôts | F3: =+Question!G5 -> 500000
A5: Frais de représentation non déductibles | F5: =+Question!G8 -> 20000 | G5: écart permanent
A7: Garantie | F7: =+Question!G10-Question!G11 -> 13000 | G7: écart temporaire
B8: (charge plus élevée que déboursés car provision augmente)
A10: Poursuite | F10: =+Question!G13 -> 50000 | G10: écart temporaire
B11: (déductible lors du règlement)
A13: Disposition de titres boursiers JVBRN
B14: Produit de disposition | E14: =+Question!G18 -> 15000 | I14: OU
B15: Coût | E15: =+Question!G17*(25/100) -> 11250 | I15: - gain comptable | K15: =-E16 -> -3750
E16: =+E14-E15 -> 3750 | F16: =-E16*0.5 -> -1875 | G16: écart permanent | I16: + gain imposable | K16: =-F16 -> 1875
A17: Plus-value comptable
B18: JV au 31 déc 2020 | E18: =+Question!G19 -> 50000
B19: Coût d'acquisition | E19: =+Question!G17*(0.75) -> 33750
E20: =+E18-E19 -> 16250 | F20: =-E20*0.5 -> -8125 | G20: écart temporaire
F21: =-0.5*E20 -> -8125 | G21: écart permanent
A23: Disposition du terrain
B24: Produit de disposition | E24: =+Question!G23 -> 40000
B25: Coût | E25: =+Question!G22 -> 100000
C26: Perte sur cession | E26: =+E24-E25 -> -60000 | F26: =+G26-K16 -> 28125 | G26: =-E26*0.5 -> 30000 | H26: déductible uniquement contre un gain en capital - portion à reporter
F27: =-0.5*E26 -> 30000 | G27: écart permanent | I27: =+K16 -> 1875 | J27: gain 2020 | K27: =+G26-I27 -> 28125
A29: Équipement | C29: Charge amortissement 2020 | F29: =+Question!G29 -> 100000
C30: Déduction pour amortissement (fiscal) | F30: =-Question!G30 -> -60000
A32: Bénéfice imposable | F32: =SUM(F3:F31) -> 663000
A34: Pertes autres qu'en capital reportées vers l'avant | F34: =-Question!G32 -> -70000 | H34: Avantage fiscal comptabilisé : | K34: =+Question!G32*Question!G36 -> 24500
F37: =SUM(F32:F34) -> 593000
A39: Taux d'impôts | F39: 0.3
A41: Impôts exigibles | F41: =+F37*F39 -> 177900
A43: Perte en capital à reporter aux années futures | E43: =+F43*2 -> 56250 | F43: =+K27 -> 28125 | G43: portion déductible
A48: Calcul des impôts différés
E49: Valeur comptable | F49: Base fiscale | G49: Écart | H49: Taux | I49: Impôts différés
B51: Prov pour garantie | D51: 2019 | E51: =+Question!G11 -> 87000 | F51: 0 | G51: =+E51-F51 -> 87000 | H51: =+Question!G$36 -> 0.35 | I51: =+G51*H51 -> 30450 | J51: Actif ID
D52: 2020 | E52: =+Question!G10 -> 100000 | F52: 0 | G52: =+E52-F52 -> 100000 | H52: =+Question!G$35 -> 0.3 | I52: =+G52*H52 -> 30000 | J52: Actif ID
I53: =+I52-I51 -> -450 | J53: diminution AID | L53: CT | M53: =+I53 -> -450
B55: Prov poursuite | D55: 2019 | E55: =+Question!G15 -> 0 | F55: 0 | G55: =+E55-F55 -> 0 | H55: =+Question!G$36 -> 0.35 | I55: =+G55*H55 -> 0 | J55: Actif ID
D56: 2020 | E56: =+Question!G13 -> 50000 | F56: 0 | G56: =+E56-F56 -> 50000 | H56: =+Question!G$35 -> 0.3 | I56: =+G56*H56 -> 15000 | J56: Actif ID
I57: =+I56-I55 -> 15000 | J57: augmentation AID | L57: DT | M57: =+I57 -> 15000
B59: Placement | D59: 2019 | E59: 0 | F59: 0 | G59: =+E59-F59 -> 0 | H59: =+Question!G$36 -> 0.35 | I59: =+G59*H59 -> 0 | J59: Passif ID
D60: 2020 | E60: =+Question!G19 -> 50000 | F60: =+E19 -> 33750 | G60: =(+E60-F60)*0.5 -> 8125 | H60: =+Question!G$35 -> 0.3 | I60: =+G60*H60 -> 2437.5 | J60: Passif ID
I61: =+I60-I59 -> 2437.5 | J61: augmentation PID | L61: CT | M61: =-I61 -> -2437.5
...
